Workbook

Sheet Settings
B1: Chemical Cleaning / Decontamination – Volume Estimate Template
B2: Fill in the yellow cells on this sheet first, then the 'Volume Calculation' sheet. The 'Summary' sheet is the proposal output.
B4: PROJECT INFORMATION
B5: Client
B6: Plant / Unit
B7: Proposal / Project No.
B8: Location
B9: Prepared by
B10: Date
B11: Revision
B13: TRAIN / UNIT NAMES (shown as column headings)
B14: Train 1 name | C14: Train 1
B15: Train 2 name | C15: Train 2
B16: Train 3 name | C16: Train 3
B17: Train 4 name | C17: Train 4
B18: Train 5 name | C18: Train 5
B20: JOB TYPE (drives the whole calculation)
B21: Job type | C21: Chemical Cleaning
B23: GENERAL PARAMETERS
B24: Water density for water-weight → volume | C24: 1000 | D24: kg/m³ | G24: Volume = water weight ÷ this density
B25: Tube pitch ratio (pitch ÷ tube OD) | C25: 1.25 | D25: – | G25: Used to estimate tube OD when only the pitch is given (TEMA typical 1.25)
B26: Drum size | C26: 200 | D26: L | G26: Chemical containers – used for the drum count on the Summary
B27: IBC / tote size | C27: 1000 | D27: L | G27: Chemical containers – used for the IBC count on the Summary
B29: METHODOLOGY – % of equipment volume considered and chemical dosage (edit per project)
B30: Equipment | C30: Chemical cleaning – fill % | D30: Decontamination – method | E30: Decon – fill % | F30: Decon – chemical % vol | G30: Remarks
B31: Exchanger | C31: 1 | D31: Vapour phase – complete volume (same as column) | E31: 1 | F31: 0.01 | G31: CC: full volume, tube side + shell side
B32: Piping | C32: 1 | D32: Vapour phase – complete volume (same as column) | E32: 1 | F32: 0.01 | G32: CC: full volume
B33: Column | C33: per item ▼ | D33: Vapour phase – column filled for complete volume | E33: 1 | F33: 0.01 | G33: CC: Full fill or 20% + gamma jet – chosen per item
B34: Vessel – Vertical | C34: per item ▼ | D34: Boil-out – water fill, steam injected at bottom (rumbling) | E34: 0.3 | F34: 0.02 | G34: CC: Full fill or 20% + gamma jet – chosen per item
B35: Vessel – Horizontal | C35: per item ▼ | D35: Boil-out – water fill, steam injected at bottom (rumbling) | E35: 0.3 | F35: 0.02 | G35: CC: Full fill or 20% + gamma jet – chosen per item
B36: Tank | C36: per item ▼ | D36: Gamma-jet circulation (heating up to 80 °C if required) | E36: 0.3 | F36: 0.02 | G36: ⚠ TO CONFIRM: decon fill % and chemical % for tanks (set equal to boil-out)
B38: CHEMICAL CLEANING – method options for vessels / columns / tanks (chosen per item)
B39: Method | C39: % of volume considered | D39: Remarks
B40: Full fill | C40: 1 | D40: Equipment completely filled with cleaning solution
B41: 20% + gamma jet circulation | C41: 0.2 | D41: Large equipment: 20% of volume circulated through gamma jetting nozzle
B43: CHEMICAL CLEANING – chemical steps (applied to the total considered volume)
B44: Step / chemical | C44: Concentration % vol | D44: No. of fills / batches | G44: Remarks
B45: EXAMPLE – Alkaline degreasing | C45: 0.02 | D45: 1 | G45: Example row – replace with the project's chemical programme
B54: LEGEND: yellow = input (blue text) · green = calculated · drop-downs are provided for units, head types, layout, basis and methods.
B55: All equipment volumes are calculated in m³. Each input row on 'Volume Calculation' has its own unit drop-down (mm, cm, m, in, ft / kg, t, lb / m³, L, gal …).
...

Sheet Volume Calculation
B1: VOLUME CALCULATION – Exchangers, Vessels / Columns / Tanks, Piping
B2: ="Client: "&ProjClient&" · Plant: "&ProjPlant&" · Proposal: "&ProjNo -> Client: · Plant: · Proposal:
B3: ="JOB TYPE: "&UPPER(JobType)&" (change on the Settings sheet)" -> JOB TYPE: CHEMICAL CLEANING (change on the Settings sheet)
B4: Enter data per train in the yellow cells (blank = not applicable). Pick the unit of each row in column C. Green rows are calculated in m³. Tip: copy a Train column to the next train when trains are identical.
A6: # | B6: Parameter | C6: Unit | D6: =TrainName1 -> Train 1 | E6: =TrainName2 -> Train 2 | F6: =TrainName3 -> Train 3 | G6: =TrainName4 -> Train 4 | H6: =TrainName5 -> Train 5 | I6: Total (all trains) | J6: Notes / source
A8: A. HEAT EXCHANGERS – tube side & shell side (20 items)
A9: 1 | B9: HEAT EXCHANGER 1
B10: Tag No. | C10: – | D10: EXAMPLE E-101 | J10: Example data in Train 1 of item 1 – overwrite or delete
B11: Service / description | C11: –
B12: TEMA type (e.g. AES, BEU) – reference | C12: –
B13: TUBE SIDE – from data sheet
B14: Number of tubes (U-tube: no. of tube holes) | C14: nos | D14: 500
B15: Tube OD | C15: mm | D15: 19.05 | J15: Leave blank if not given – estimated from tube pitch ÷ pitch ratio
B16: Tube ID | C16: mm | D16: 15.75
B17: Tube length (straight length per tube) | C17: mm | D17: 6096
B18: Tube pitch | C18: mm | D18: 23.81 | J18: Used when tube OD and/or shell ID are not given
B19: Tube layout | C19: – | D19: Triangular (30°) | E19: Triangular (30°) | F19: Triangular (30°) | G19: Triangular (30°) | H19: Triangular (30°)
B20: Front channel / bonnet ID | C20: mm | D20: 800
B21: Front channel cylindrical length | C21: mm | D21: 600
B22: Front head / cover type | C22: – | D22: Flat
B23: Rear channel / bonnet ID (blank for U-tube) | C23: mm | D23: 800
B24: Rear channel cylindrical length | C24: mm | D24: 300
B25: Rear head / cover type | C25: – | D25: 2:1 Ellipsoidal
B26: Channel / bonnet volume – if given on data sheet | C26: m³ | J26: If filled, overrides the channel dimensions above
B27: Tube side water weight – if given | C27: kg
B28: SHELL SIDE – from data sheet
B29: Shell ID | C29: mm | D29: 800 | J29: If blank: area estimated as no. of tubes × pitch² × layout factor
B30: Shell length (tubesheet to tubesheet / cover) | C30: mm | D30: 6000 | J30: If blank, tube length is used
B31: Shell cover / head type (e.g. U-tube or floating head cover) | C31: –
B32: Shell side water weight – if given | C32: kg
B33: VOLUME BASIS – choose per item
B34: Tube side basis | C34: – | D34: Dimensions | E34: Dimensions | F34: Dimensions | G34: Dimensions | H34: Dimensions
B35: Shell side basis | C35: – | D35: Dimensions | E35: Dimensions | F35: Dimensions | G35: Dimensions | H35: Dimensions
B36: CALCULATION
B37: Tube OD used | C37: mm | D37: =IF(ISNUMBER(D15),D15*INDEX(LenF,MATCH($C$15,LenU,0))*1000,IF(ISNUMBER(D18),D18*INDEX(LenF,MATCH($C$18,LenU,0))/PitchRatio*1000,"")) -> 19.05 | E37: =IF(ISNUMBER(E15),E15*INDEX(LenF,MATCH($C$15,LenU,0))*1000,IF(ISNUMBER(E18),E18*INDEX(LenF,MATCH($C$18,LenU,0))/PitchRatio*1000,"")) | F37: =IF(ISNUMBER(F15),F15*INDEX(LenF,MATCH($C$15,LenU,0))*1000,IF(ISNUMBER(F18),F18*INDEX(LenF,MATCH($C$18,LenU,0))/PitchRatio*1000,"")) | G37: =IF(ISNUMBER(G15),G15*INDEX(LenF,MATCH($C$15,LenU,0))*1000,IF(ISNUMBER(G18),G18*INDEX(LenF,MATCH($C$18,LenU,0))/PitchRatio*1000,"")) | H37: =IF(ISNUMBER(H15),H15*INDEX(LenF,MATCH($C$15,LenU,0))*1000,IF(ISNUMBER(H18),H18*INDEX(LenF,MATCH($C$18,LenU,0))/PitchRatio*1000,"")) | J37: Given OD, or pitch ÷ pitch ratio (Settings) when OD is blank
B38: Tubes internal volume (N × π/4 × ID² × L) | C38: m³ | D38: =IF(AND(ISNUMBER(D14),ISNUMBER(D16),ISNUMBER(D17)),D14*PI()/4*(D16*INDEX(LenF,MATCH($C$16,LenU,0)))^2*D17*INDEX(LenF,MATCH($C$17,LenU,0)),"") -> 0.59383523 | E38: =IF(AND(ISNUMBER(E14),ISNUMBER(E16),ISNUMBER(E17)),E14*PI()/4*(E16*INDEX(LenF,MATCH($C$16,LenU,0)))^2*E17*INDEX(LenF,MATCH($C$17,LenU,0)),"") | F38: =IF(AND(ISNUMBER(F14),ISNUMBER(F16),ISNUMBER(F17)),F14*PI()/4*(F16*INDEX(LenF,MATCH($C$16,LenU,0)))^2*F17*INDEX(LenF,MATCH($C$17,LenU,0)),"") | G38: =IF(AND(ISNUMBER(G14),ISNUMBER(G16),ISNUMBER(G17)),G14*PI()/4*(G16*INDEX(LenF,MATCH($C$16,LenU,0)))^2*G17*INDEX(LenF,MATCH($C$17,LenU,0)),"") | H38: =IF(AND(ISNUMBER(H14),ISNUMBER(H16),ISNUMBER(H17)),H14*PI()/4*(H16*INDEX(LenF,MATCH($C$16,LenU,0)))^2*H17*INDEX(LenF,MATCH($C$17,LenU,0)),"") | I38: =IF(COUNT(D38:H38)=0,"",SUM(D38:H38)) -> 0.59383523
B39: Channel / bonnet volume (front + rear) | C39: m³ | D39: =IF(ISNUMBER(D26),D26*INDEX(VolF,MATCH($C$26,VolU,0)),IF(ISNUMBER(D20),PI()/4*(D20*INDEX(LenF,MATCH($C$20,LenU,0)))^2*N(D21)*INDEX(LenF,MATCH($C$21,LenU,0))+IF(D22="",0,IF(D22="Conical",PI()/12*(D20*INDEX(LenF,MATCH($C$20,LenU,0)))^2*(0),INDEX(HeadK,MATCH(D22,HeadU,0))*(D20*INDEX(LenF,MATCH($C$20,LenU,0)))^3)),0)+IF(ISNUMBER(D23),PI()/4*(D23*INDEX(LenF,MATCH($C$23,LenU,0)))^2*N(D24)*INDEX(LenF,MATCH($C$24,LenU,0))+IF(D25="",0,IF(D25="Conical",PI()/12*(D23*INDEX(LenF,MATCH($C$23,LenU,0)))^2*(0),INDEX(HeadK,MATCH(D25,HeadU,0))*(D23*INDEX(LenF,MATCH($C$23,LenU,0)))^3)),0)) -> 0.51940999 | E39: =IF(ISNUMBER(E26),E26*INDEX(VolF,MATCH($C$26,VolU,0)),IF(ISNUMBER(E20),PI()/4*(E20*INDEX(LenF,MATCH($C$20,LenU,0)))^2*N(E21)*INDEX(LenF,MATCH($C$21,LenU,0))+IF(E22="",0,IF(E22="Conical",PI()/12*(E20*INDEX(LenF,MATCH($C$20,LenU,0)))^2*(0),INDEX(HeadK,MATCH(E22,HeadU,0))*(E20*INDEX(LenF,MATCH($C$20,LenU,0)))^3)),0)+IF(ISNUMBER(E23),PI()/4*(E23*INDEX(LenF,MATCH($C$23,LenU,0)))^2*N(E24)*INDEX(LenF,MATCH($C$24,LenU,0))+IF(E25="",0,IF(E25="Conical",PI()/12*(E23*INDEX(LenF,MATCH($C$23,LenU,0)))^2*(0),INDEX(HeadK,MATCH(E25,HeadU,0))*(E23*INDEX(LenF,MATCH($C$23,LenU,0)))^3)),0)) -> 0 | F39: =IF(ISNUMBER(F26),F26*INDEX(VolF,MATCH($C$26,VolU,0)),IF(ISNUMBER(F20),PI()/4*(F20*INDEX(LenF,MATCH($C$20,LenU,0)))^2*N(F21)*INDEX(LenF,MATCH($C$21,LenU,0))+IF(F22="",0,IF(F22="Conical",PI()/12*(F20*INDEX(LenF,MATCH($C$20,LenU,0)))^2*(0),INDEX(HeadK,MATCH(F22,HeadU,0))*(F20*INDEX(LenF,MATCH($C$20,LenU,0)))^3)),0)+IF(ISNUMBER(F23),PI()/4*(F23*INDEX(LenF,MATCH($C$23,LenU,0)))^2*N(F24)*INDEX(LenF,MATCH($C$24,LenU,0))+IF(F25="",0,IF(F25="Conical",PI()/12*(F23*INDEX(LenF,MATCH($C$23,LenU,0)))^2*(0),INDEX(HeadK,MATCH(F25,HeadU,0))*(F23*INDEX(LenF,MATCH($C$23,LenU,0)))^3)),0)) -> 0 | G39: =IF(ISNUMBER(G26),G26*INDEX(VolF,MATCH($C$26,VolU,0)),IF(ISNUMBER(G20),PI()/4*(G20*INDEX(LenF,MATCH($C$20,LenU,0)))^2*N(G21)*INDEX(LenF,MATCH($C$21,LenU,0))+IF(G22="",0,IF(G22="Conical",PI()/12*(G20*INDEX(LenF,MATCH($C$20,LenU,0)))^2*(0),INDEX(HeadK,MATCH(G22,HeadU,0))*(G20*INDEX(LenF,MATCH($C$20,LenU,0)))^3)),0)+IF(ISNUMBER(G23),PI()/4*(G23*INDEX(LenF,MATCH($C$23,LenU,0)))^2*N(G24)*INDEX(LenF,MATCH($C$24,LenU,0))+IF(G25="",0,IF(G25="Conical",PI()/12*(G23*INDEX(LenF,MATCH($C$23,LenU,0)))^2*(0),INDEX(HeadK,MATCH(G25,HeadU,0))*(G23*INDEX(LenF,MATCH($C$23,LenU,0)))^3)),0)) -> 0 | H39: =IF(ISNUMBER(H26),H26*INDEX(VolF,MATCH($C$26,VolU,0)),IF(ISNUMBER(H20),PI()/4*(H20*INDEX(LenF,MATCH($C$20,LenU,0)))^2*N(H21)*INDEX(LenF,MATCH($C$21,LenU,0))+IF(H22="",0,IF(H22="Conical",PI()/12*(H20*INDEX(LenF,MATCH($C$20,LenU,0)))^2*(0),INDEX(HeadK,MATCH(H22,HeadU,0))*(H20*INDEX(LenF,MATCH($C$20,LenU,0)))^3)),0)+IF(ISNUMBER(H23),PI()/4*(H23*INDEX(LenF,MATCH($C$23,LenU,0)))^2*N(H24)*INDEX(LenF,MATCH($C$24,LenU,0))+IF(H25="",0,IF(H25="Conical",PI()/12*(H23*INDEX(LenF,MATCH($C$23,LenU,0)))^2*(0),INDEX(HeadK,MATCH(H25,HeadU,0))*(H23*INDEX(LenF,MATCH($C$23,LenU,0)))^3)),0)) -> 0 | I39: =IF(COUNT(D39:H39)=0,"",SUM(D39:H39)) -> 0.51940999 | J39: Given volume, else cylinder + head for front and rear
B40: Tube side volume – from dimensions | C40: m³ | D40: =IF(D38="","",D38+D39) -> 1.1132452 | E40: =IF(E38="","",E38+E39) | F40: =IF(F38="","",F38+F39) | G40: =IF(G38="","",G38+G39) | H40: =IF(H38="","",H38+H39) | I40: =IF(COUNT(D40:H40)=0,"",SUM(D40:H40)) -> 1.1132452
B41: Tube side volume – from water weight | C41: m³ | D41: =IF(ISNUMBER(D27),D27*INDEX(WtF,MATCH($C$27,WtU,0))/WaterRho,"") | E41: =IF(ISNUMBER(E27),E27*INDEX(WtF,MATCH($C$27,WtU,0))/WaterRho,"") | F41: =IF(ISNUMBER(F27),F27*INDEX(WtF,MATCH($C$27,WtU,0))/WaterRho,"") | G41: =IF(ISNUMBER(G27),G27*INDEX(WtF,MATCH($C$27,WtU,0))/WaterRho,"") | H41: =IF(ISNUMBER(H27),H27*INDEX(WtF,MATCH($C$27,WtU,0))/WaterRho,"") | I41: =IF(COUNT(D41:H41)=0,"",SUM(D41:H41))
B42: TUBE SIDE VOLUME (selected basis) | C42: m³ | D42: =IF(D34="Water weight",D41,D40) -> 1.1132452 | E42: =IF(E34="Water weight",E41,E40) | F42: =IF(F34="Water weight",F41,F40) | G42: =IF(G34="Water weight",G41,G40) | H42: =IF(H34="Water weight",H41,H40) | I42: =IF(COUNT(D42:H42)=0,"",SUM(D42:H42)) -> 1.1132452 | K42: HX_TS
...

Sheet Summary
B1: ="VOLUME & CHEMICAL SUMMARY – "&UPPER(JobType) -> VOLUME & CHEMICAL SUMMARY – CHEMICAL CLEANING
B2: ="Client: "&ProjClient&" · Plant: "&ProjPlant&" · Proposal: "&ProjNo -> Client: · Plant: · Proposal:
B3: =IF(COUNTIF('Volume Calculation'!D10:H10,"EXAMPLE*")+COUNTIF('Volume Calculation'!D912:H912,"EXAMPLE*")+COUNTIF('Volume Calculation'!D1454:H1454,"EXAMPLE*")>0,"⚠ Example data is still present (Tag starting with EXAMPLE) – delete it before issuing the proposal.","") -> ⚠ Example data is still present (Tag starting with EXAMPLE) – delete it before issuing the proposal.
B5: 1. EQUIPMENT VOLUMES (full volume, selected basis)
B6: Item | C6: Unit | D6: =TrainName1 -> Train 1 | E6: =TrainName2 -> Train 2 | F6: =TrainName3 -> Train 3 | G6: =TrainName4 -> Train 4 | H6: =TrainName5 -> Train 5 | I6: Total
B7: Heat exchangers – tube side | C7: m³ | D7: =SUMIFS('Volume Calculation'!D:D,'Volume Calculation'!$K:$K,"HX_TS") -> 1.1132452 | E7: =SUMIFS('Volume Calculation'!E:E,'Volume Calculation'!$K:$K,"HX_TS") -> 0 | F7: =SUMIFS('Volume Calculation'!F:F,'Volume Calculation'!$K:$K,"HX_TS") -> 0 | G7: =SUMIFS('Volume Calculation'!G:G,'Volume Calculation'!$K:$K,"HX_TS") -> 0 | H7: =SUMIFS('Volume Calculation'!H:H,'Volume Calculation'!$K:$K,"HX_TS") -> 0 | I7: =SUM(D7:H7) -> 1.1132452
B8: Heat exchangers – shell side | C8: m³ | D8: =SUMIFS('Volume Calculation'!D:D,'Volume Calculation'!$K:$K,"HX_SS") -> 2.147179 | E8: =SUMIFS('Volume Calculation'!E:E,'Volume Calculation'!$K:$K,"HX_SS") -> 0 | F8: =SUMIFS('Volume Calculation'!F:F,'Volume Calculation'!$K:$K,"HX_SS") -> 0 | G8: =SUMIFS('Volume Calculation'!G:G,'Volume Calculation'!$K:$K,"HX_SS") -> 0 | H8: =SUMIFS('Volume Calculation'!H:H,'Volume Calculation'!$K:$K,"HX_SS") -> 0 | I8: =SUM(D8:H8) -> 2.147179
B9: Vessels – vertical | C9: m³ | D9: =SUMIFS('Volume Calculation'!D:D,'Volume Calculation'!$K:$K,"V_SEL",'Volume Calculation'!$L:$L,"Vessel – Vertical") -> 20.943951 | E9: =SUMIFS('Volume Calculation'!E:E,'Volume Calculation'!$K:$K,"V_SEL",'Volume Calculation'!$M:$M,"Vessel – Vertical") -> 0 | F9: =SUMIFS('Volume Calculation'!F:F,'Volume Calculation'!$K:$K,"V_SEL",'Volume Calculation'!$N:$N,"Vessel – Vertical") -> 0 | G9: =SUMIFS('Volume Calculation'!G:G,'Volume Calculation'!$K:$K,"V_SEL",'Volume Calculation'!$O:$O,"Vessel – Vertical") -> 0 | H9: =SUMIFS('Volume Calculation'!H:H,'Volume Calculation'!$K:$K,"V_SEL",'Volume Calculation'!$P:$P,"Vessel – Vertical") -> 0 | I9: =SUM(D9:H9) -> 20.943951
B10: Vessels – horizontal | C10: m³ | D10: =SUMIFS('Volume Calculation'!D:D,'Volume Calculation'!$K:$K,"V_SEL",'Volume Calculation'!$L:$L,"Vessel – Horizontal") -> 0 | E10: =SUMIFS('Volume Calculation'!E:E,'Volume Calculation'!$K:$K,"V_SEL",'Volume Calculation'!$M:$M,"Vessel – Horizontal") -> 0 | F10: =SUMIFS('Volume Calculation'!F:F,'Volume Calculation'!$K:$K,"V_SEL",'Volume Calculation'!$N:$N,"Vessel – Horizontal") -> 0 | G10: =SUMIFS('Volume Calculation'!G:G,'Volume Calculation'!$K:$K,"V_SEL",'Volume Calculation'!$O:$O,"Vessel – Horizontal") -> 0 | H10: =SUMIFS('Volume Calculation'!H:H,'Volume Calculation'!$K:$K,"V_SEL",'Volume Calculation'!$P:$P,"Vessel – Horizontal") -> 0 | I10: =SUM(D10:H10) -> 0
B11: Columns | C11: m³ | D11: =SUMIFS('Volume Calculation'!D:D,'Volume Calculation'!$K:$K,"V_SEL",'Volume Calculation'!$L:$L,"Column") -> 0 | E11: =SUMIFS('Volume Calculation'!E:E,'Volume Calculation'!$K:$K,"V_SEL",'Volume Calculation'!$M:$M,"Column") -> 0 | F11: =SUMIFS('Volume Calculation'!F:F,'Volume Calculation'!$K:$K,"V_SEL",'Volume Calculation'!$N:$N,"Column") -> 0 | G11: =SUMIFS('Volume Calculation'!G:G,'Volume Calculation'!$K:$K,"V_SEL",'Volume Calculation'!$O:$O,"Column") -> 0 | H11: =SUMIFS('Volume Calculation'!H:H,'Volume Calculation'!$K:$K,"V_SEL",'Volume Calculation'!$P:$P,"Column") -> 0 | I11: =SUM(D11:H11) -> 0
B12: Tanks | C12: m³ | D12: =SUMIFS('Volume Calculation'!D:D,'Volume Calculation'!$K:$K,"V_SEL",'Volume Calculation'!$L:$L,"Tank") -> 0 | E12: =SUMIFS('Volume Calculation'!E:E,'Volume Calculation'!$K:$K,"V_SEL",'Volume Calculation'!$M:$M,"Tank") -> 0 | F12: =SUMIFS('Volume Calculation'!F:F,'Volume Calculation'!$K:$K,"V_SEL",'Volume Calculation'!$N:$N,"Tank") -> 0 | G12: =SUMIFS('Volume Calculation'!G:G,'Volume Calculation'!$K:$K,"V_SEL",'Volume Calculation'!$O:$O,"Tank") -> 0 | H12: =SUMIFS('Volume Calculation'!H:H,'Volume Calculation'!$K:$K,"V_SEL",'Volume Calculation'!$P:$P,"Tank") -> 0 | I12: =SUM(D12:H12) -> 0
B13: Vessels with no equipment type selected | C13: m³ | D13: =SUMIFS('Volume Calculation'!D:D,'Volume Calculation'!$K:$K,"V_SEL")-SUM(D9,D10,D11,D12) -> 0 | E13: =SUMIFS('Volume Calculation'!E:E,'Volume Calculation'!$K:$K,"V_SEL")-SUM(E9,E10,E11,E12) -> 0 | F13: =SUMIFS('Volume Calculation'!F:F,'Volume Calculation'!$K:$K,"V_SEL")-SUM(F9,F10,F11,F12) -> 0 | G13: =SUMIFS('Volume Calculation'!G:G,'Volume Calculation'!$K:$K,"V_SEL")-SUM(G9,G10,G11,G12) -> 0 | H13: =SUMIFS('Volume Calculation'!H:H,'Volume Calculation'!$K:$K,"V_SEL")-SUM(H9,H10,H11,H12) -> 0 | I13: =SUM(D13:H13) -> 0
B14: Piping | C14: m³ | D14: =SUMIFS('Volume Calculation'!D:D,'Volume Calculation'!$K:$K,"P_VOL") -> 2.2375032 | E14: =SUMIFS('Volume Calculation'!E:E,'Volume Calculation'!$K:$K,"P_VOL") -> 0 | F14: =SUMIFS('Volume Calculation'!F:F,'Volume Calculation'!$K:$K,"P_VOL") -> 0 | G14: =SUMIFS('Volume Calculation'!G:G,'Volume Calculation'!$K:$K,"P_VOL") -> 0 | H14: =SUMIFS('Volume Calculation'!H:H,'Volume Calculation'!$K:$K,"P_VOL") -> 0 | I14: =SUM(D14:H14) -> 2.2375032
B15: TOTAL SYSTEM VOLUME | C15: m³ | D15: =SUM(D7:D14) -> 26.441878 | E15: =SUM(E7:E14) -> 0 | F15: =SUM(F7:F14) -> 0 | G15: =SUM(G7:G14) -> 0 | H15: =SUM(H7:H14) -> 0 | I15: =SUM(D15:H15) -> 26.441878
B16: TOTAL SYSTEM VOLUME | C16: L | D16: =D15*1000 -> 26441.878 | E16: =E15*1000 -> 0 | F16: =F15*1000 -> 0 | G16: =G15*1000 -> 0 | H16: =H15*1000 -> 0 | I16: =SUM(D16:H16) -> 26441.878
B17: TOTAL SYSTEM VOLUME | C17: US gal | D17: =D15/0.003785411784 -> 6985.2053 | E17: =E15/0.003785411784 -> 0 | F17: =F15/0.003785411784 -> 0 | G17: =G15/0.003785411784 -> 0 | H17: =H15/0.003785411784 -> 0 | I17: =SUM(D17:H17) -> 6985.2053
B19: 2. CONSIDERED VOLUME FOR THE SELECTED JOB TYPE (% per Settings / per-item method)
B20: Item | C20: Unit | D20: =TrainName1 -> Train 1 | E20: =TrainName2 -> Train 2 | F20: =TrainName3 -> Train 3 | G20: =TrainName4 -> Train 4 | H20: =TrainName5 -> Train 5 | I20: Total
B21: Heat exchangers (tube + shell side) | C21: m³ | D21: =SUMIFS('Volume Calculation'!D:D,'Volume Calculation'!$K:$K,"HX_CONS") -> 3.2604242 | E21: =SUMIFS('Volume Calculation'!E:E,'Volume Calculation'!$K:$K,"HX_CONS") -> 0 | F21: =SUMIFS('Volume Calculation'!F:F,'Volume Calculation'!$K:$K,"HX_CONS") -> 0 | G21: =SUMIFS('Volume Calculation'!G:G,'Volume Calculation'!$K:$K,"HX_CONS") -> 0 | H21: =SUMIFS('Volume Calculation'!H:H,'Volume Calculation'!$K:$K,"HX_CONS") -> 0 | I21: =SUM(D21:H21) -> 3.2604242
B22: Vessels – vertical | C22: m³ | D22: =SUMIFS('Volume Calculation'!D:D,'Volume Calculation'!$K:$K,"V_CONS",'Volume Calculation'!$L:$L,"Vessel – Vertical") -> 20.943951 | E22: =SUMIFS('Volume Calculation'!E:E,'Volume Calculation'!$K:$K,"V_CONS",'Volume Calculation'!$M:$M,"Vessel – Vertical") -> 0 | F22: =SUMIFS('Volume Calculation'!F:F,'Volume Calculation'!$K:$K,"V_CONS",'Volume Calculation'!$N:$N,"Vessel – Vertical") -> 0 | G22: =SUMIFS('Volume Calculation'!G:G,'Volume Calculation'!$K:$K,"V_CONS",'Volume Calculation'!$O:$O,"Vessel – Vertical") -> 0 | H22: =SUMIFS('Volume Calculation'!H:H,'Volume Calculation'!$K:$K,"V_CONS",'Volume Calculation'!$P:$P,"Vessel – Vertical") -> 0 | I22: =SUM(D22:H22) -> 20.943951
B23: Vessels – horizontal | C23: m³ | D23: =SUMIFS('Volume Calculation'!D:D,'Volume Calculation'!$K:$K,"V_CONS",'Volume Calculation'!$L:$L,"Vessel – Horizontal") -> 0 | E23: =SUMIFS('Volume Calculation'!E:E,'Volume Calculation'!$K:$K,"V_CONS",'Volume Calculation'!$M:$M,"Vessel – Horizontal") -> 0 | F23: =SUMIFS('Volume Calculation'!F:F,'Volume Calculation'!$K:$K,"V_CONS",'Volume Calculation'!$N:$N,"Vessel – Horizontal") -> 0 | G23: =SUMIFS('Volume Calculation'!G:G,'Volume Calculation'!$K:$K,"V_CONS",'Volume Calculation'!$O:$O,"Vessel – Horizontal") -> 0 | H23: =SUMIFS('Volume Calculation'!H:H,'Volume Calculation'!$K:$K,"V_CONS",'Volume Calculation'!$P:$P,"Vessel – Horizontal") -> 0 | I23: =SUM(D23:H23) -> 0
B24: Columns | C24: m³ | D24: =SUMIFS('Volume Calculation'!D:D,'Volume Calculation'!$K:$K,"V_CONS",'Volume Calculation'!$L:$L,"Column") -> 0 | E24: =SUMIFS('Volume Calculation'!E:E,'Volume Calculation'!$K:$K,"V_CONS",'Volume Calculation'!$M:$M,"Column") -> 0 | F24: =SUMIFS('Volume Calculation'!F:F,'Volume Calculation'!$K:$K,"V_CONS",'Volume Calculation'!$N:$N,"Column") -> 0 | G24: =SUMIFS('Volume Calculation'!G:G,'Volume Calculation'!$K:$K,"V_CONS",'Volume Calculation'!$O:$O,"Column") -> 0 | H24: =SUMIFS('Volume Calculation'!H:H,'Volume Calculation'!$K:$K,"V_CONS",'Volume Calculation'!$P:$P,"Column") -> 0 | I24: =SUM(D24:H24) -> 0
B25: Tanks | C25: m³ | D25: =SUMIFS('Volume Calculation'!D:D,'Volume Calculation'!$K:$K,"V_CONS",'Volume Calculation'!$L:$L,"Tank") -> 0 | E25: =SUMIFS('Volume Calculation'!E:E,'Volume Calculation'!$K:$K,"V_CONS",'Volume Calculation'!$M:$M,"Tank") -> 0 | F25: =SUMIFS('Volume Calculation'!F:F,'Volume Calculation'!$K:$K,"V_CONS",'Volume Calculation'!$N:$N,"Tank") -> 0 | G25: =SUMIFS('Volume Calculation'!G:G,'Volume Calculation'!$K:$K,"V_CONS",'Volume Calculation'!$O:$O,"Tank") -> 0 | H25: =SUMIFS('Volume Calculation'!H:H,'Volume Calculation'!$K:$K,"V_CONS",'Volume Calculation'!$P:$P,"Tank") -> 0 | I25: =SUM(D25:H25) -> 0
B26: Vessels with no equipment type selected | C26: m³ | D26: =SUMIFS('Volume Calculation'!D:D,'Volume Calculation'!$K:$K,"V_CONS")-SUM(D22,D23,D24,D25) -> 0 | E26: =SUMIFS('Volume Calculation'!E:E,'Volume Calculation'!$K:$K,"V_CONS")-SUM(E22,E23,E24,E25) -> 0 | F26: =SUMIFS('Volume Calculation'!F:F,'Volume Calculation'!$K:$K,"V_CONS")-SUM(F22,F23,F24,F25) -> 0 | G26: =SUMIFS('Volume Calculation'!G:G,'Volume Calculation'!$K:$K,"V_CONS")-SUM(G22,G23,G24,G25) -> 0 | H26: =SUMIFS('Volume Calculation'!H:H,'Volume Calculation'!$K:$K,"V_CONS")-SUM(H22,H23,H24,H25) -> 0 | I26: =SUM(D26:H26) -> 0
B27: Piping | C27: m³ | D27: =SUMIFS('Volume Calculation'!D:D,'Volume Calculation'!$K:$K,"P_CONS") -> 2.2375032 | E27: =SUMIFS('Volume Calculation'!E:E,'Volume Calculation'!$K:$K,"P_CONS") -> 0 | F27: =SUMIFS('Volume Calculation'!F:F,'Volume Calculation'!$K:$K,"P_CONS") -> 0 | G27: =SUMIFS('Volume Calculation'!G:G,'Volume Calculation'!$K:$K,"P_CONS") -> 0 | H27: =SUMIFS('Volume Calculation'!H:H,'Volume Calculation'!$K:$K,"P_CONS") -> 0 | I27: =SUM(D27:H27) -> 2.2375032
B28: TOTAL CONSIDERED VOLUME (water / solution) | C28: m³ | D28: =SUM(D21:D27) -> 26.441878 | E28: =SUM(E21:E27) -> 0 | F28: =SUM(F21:F27) -> 0 | G28: =SUM(G21:G27) -> 0 | H28: =SUM(H21:H27) -> 0 | I28: =SUM(D28:H28) -> 26.441878
B29: TOTAL CONSIDERED VOLUME | C29: L | D29: =D28*1000 -> 26441.878 | E29: =E28*1000 -> 0 | F29: =F28*1000 -> 0 | G29: =G28*1000 -> 0 | H29: =H28*1000 -> 0 | I29: =SUM(D29:H29) -> 26441.878
B31: 3A. CHEMICAL CLEANING – chemical per step (= total considered volume × concentration × fills)
B32: Item | C32: Unit | D32: =TrainName1 -> Train 1 | E32: =TrainName2 -> Train 2 | F32: =TrainName3 -> Train 3 | G32: =TrainName4 -> Train 4 | H32: =TrainName5 -> Train 5 | I32: Total
B33: =IF(JobType<>"Chemical Cleaning","(Not applicable – job type is "&JobType&")","")
B34: =IF(Settings!$B$45="","Step 1 (not used)",Settings!$B$45&" @ "&TEXT(Settings!$C$45,"0.0%")&" × "&N(Settings!$D$45)&" fill(s)") -> EXAMPLE – Alkaline degreasing @ 2.0% × 1 fill(s) | C34: L | D34: =IF(OR(JobType<>"Chemical Cleaning",Settings!$C$45=""),0,D28*1000*Settings!$C$45*IF(N(Settings!$D$45)=0,1,Settings!$D$45)) -> 528.83757 | E34: =IF(OR(JobType<>"Chemical Cleaning",Settings!$C$45=""),0,E28*1000*Settings!$C$45*IF(N(Settings!$D$45)=0,1,Settings!$D$45)) -> 0 | F34: =IF(OR(JobType<>"Chemical Cleaning",Settings!$C$45=""),0,F28*1000*Settings!$C$45*IF(N(Settings!$D$45)=0,1,Settings!$D$45)) -> 0 | G34: =IF(OR(JobType<>"Chemical Cleaning",Settings!$C$45=""),0,G28*1000*Settings!$C$45*IF(N(Settings!$D$45)=0,1,Settings!$D$45)) -> 0 | H34: =IF(OR(JobType<>"Chemical Cleaning",Settings!$C$45=""),0,H28*1000*Settings!$C$45*IF(N(Settings!$D$45)=0,1,Settings!$D$45)) -> 0 | I34: =SUM(D34:H34) -> 528.83757
B35: =IF(Settings!$B$46="","Step 2 (not used)",Settings!$B$46&" @ "&TEXT(Settings!$C$46,"0.0%")&" × "&N(Settings!$D$46)&" fill(s)") -> Step 2 (not used) | C35: L | D35: =IF(OR(JobType<>"Chemical Cleaning",Settings!$C$46=""),0,D28*1000*Settings!$C$46*IF(N(Settings!$D$46)=0,1,Settings!$D$46)) -> 0 | E35: =IF(OR(JobType<>"Chemical Cleaning",Settings!$C$46=""),0,E28*1000*Settings!$C$46*IF(N(Settings!$D$46)=0,1,Settings!$D$46)) -> 0 | F35: =IF(OR(JobType<>"Chemical Cleaning",Settings!$C$46=""),0,F28*1000*Settings!$C$46*IF(N(Settings!$D$46)=0,1,Settings!$D$46)) -> 0 | G35: =IF(OR(JobType<>"Chemical Cleaning",Settings!$C$46=""),0,G28*1000*Settings!$C$46*IF(N(Settings!$D$46)=0,1,Settings!$D$46)) -> 0 | H35: =IF(OR(JobType<>"Chemical Cleaning",Settings!$C$46=""),0,H28*1000*Settings!$C$46*IF(N(Settings!$D$46)=0,1,Settings!$D$46)) -> 0 | I35: =SUM(D35:H35) -> 0
B36: =IF(Settings!$B$47="","Step 3 (not used)",Settings!$B$47&" @ "&TEXT(Settings!$C$47,"0.0%")&" × "&N(Settings!$D$47)&" fill(s)") -> Step 3 (not used) | C36: L | D36: =IF(OR(JobType<>"Chemical Cleaning",Settings!$C$47=""),0,D28*1000*Settings!$C$47*IF(N(Settings!$D$47)=0,1,Settings!$D$47)) -> 0 | E36: =IF(OR(JobType<>"Chemical Cleaning",Settings!$C$47=""),0,E28*1000*Settings!$C$47*IF(N(Settings!$D$47)=0,1,Settings!$D$47)) -> 0 | F36: =IF(OR(JobType<>"Chemical Cleaning",Settings!$C$47=""),0,F28*1000*Settings!$C$47*IF(N(Settings!$D$47)=0,1,Settings!$D$47)) -> 0 | G36: =IF(OR(JobType<>"Chemical Cleaning",Settings!$C$47=""),0,G28*1000*Settings!$C$47*IF(N(Settings!$D$47)=0,1,Settings!$D$47)) -> 0 | H36: =IF(OR(JobType<>"Chemical Cleaning",Settings!$C$47=""),0,H28*1000*Settings!$C$47*IF(N(Settings!$D$47)=0,1,Settings!$D$47)) -> 0 | I36: =SUM(D36:H36) -> 0
B37: =IF(Settings!$B$48="","Step 4 (not used)",Settings!$B$48&" @ "&TEXT(Settings!$C$48,"0.0%")&" × "&N(Settings!$D$48)&" fill(s)") -> Step 4 (not used) | C37: L | D37: =IF(OR(JobType<>"Chemical Cleaning",Settings!$C$48=""),0,D28*1000*Settings!$C$48*IF(N(Settings!$D$48)=0,1,Settings!$D$48)) -> 0 | E37: =IF(OR(JobType<>"Chemical Cleaning",Settings!$C$48=""),0,E28*1000*Settings!$C$48*IF(N(Settings!$D$48)=0,1,Settings!$D$48)) -> 0 | F37: =IF(OR(JobType<>"Chemical Cleaning",Settings!$C$48=""),0,F28*1000*Settings!$C$48*IF(N(Settings!$D$48)=0,1,Settings!$D$48)) -> 0 | G37: =IF(OR(JobType<>"Chemical Cleaning",Settings!$C$48=""),0,G28*1000*Settings!$C$48*IF(N(Settings!$D$48)=0,1,Settings!$D$48)) -> 0 | H37: =IF(OR(JobType<>"Chemical Cleaning",Settings!$C$48=""),0,H28*1000*Settings!$C$48*IF(N(Settings!$D$48)=0,1,Settings!$D$48)) -> 0 | I37: =SUM(D37:H37) -> 0
B38: =IF(Settings!$B$49="","Step 5 (not used)",Settings!$B$49&" @ "&TEXT(Settings!$C$49,"0.0%")&" × "&N(Settings!$D$49)&" fill(s)") -> Step 5 (not used) | C38: L | D38: =IF(OR(JobType<>"Chemical Cleaning",Settings!$C$49=""),0,D28*1000*Settings!$C$49*IF(N(Settings!$D$49)=0,1,Settings!$D$49)) -> 0 | E38: =IF(OR(JobType<>"Chemical Cleaning",Settings!$C$49=""),0,E28*1000*Settings!$C$49*IF(N(Settings!$D$49)=0,1,Settings!$D$49)) -> 0 | F38: =IF(OR(JobType<>"Chemical Cleaning",Settings!$C$49=""),0,F28*1000*Settings!$C$49*IF(N(Settings!$D$49)=0,1,Settings!$D$49)) -> 0 | G38: =IF(OR(JobType<>"Chemical Cleaning",Settings!$C$49=""),0,G28*1000*Settings!$C$49*IF(N(Settings!$D$49)=0,1,Settings!$D$49)) -> 0 | H38: =IF(OR(JobType<>"Chemical Cleaning",Settings!$C$49=""),0,H28*1000*Settings!$C$49*IF(N(Settings!$D$49)=0,1,Settings!$D$49)) -> 0 | I38: =SUM(D38:H38) -> 0
B39: =IF(Settings!$B$50="","Step 6 (not used)",Settings!$B$50&" @ "&TEXT(Settings!$C$50,"0.0%")&" × "&N(Settings!$D$50)&" fill(s)") -> Step 6 (not used) | C39: L | D39: =IF(OR(JobType<>"Chemical Cleaning",Settings!$C$50=""),0,D28*1000*Settings!$C$50*IF(N(Settings!$D$50)=0,1,Settings!$D$50)) -> 0 | E39: =IF(OR(JobType<>"Chemical Cleaning",Settings!$C$50=""),0,E28*1000*Settings!$C$50*IF(N(Settings!$D$50)=0,1,Settings!$D$50)) -> 0 | F39: =IF(OR(JobType<>"Chemical Cleaning",Settings!$C$50=""),0,F28*1000*Settings!$C$50*IF(N(Settings!$D$50)=0,1,Settings!$D$50)) -> 0 | G39: =IF(OR(JobType<>"Chemical Cleaning",Settings!$C$50=""),0,G28*1000*Settings!$C$50*IF(N(Settings!$D$50)=0,1,Settings!$D$50)) -> 0 | H39: =IF(OR(JobType<>"Chemical Cleaning",Settings!$C$50=""),0,H28*1000*Settings!$C$50*IF(N(Settings!$D$50)=0,1,Settings!$D$50)) -> 0 | I39: =SUM(D39:H39) -> 0
B40: =IF(Settings!$B$51="","Step 7 (not used)",Settings!$B$51&" @ "&TEXT(Settings!$C$51,"0.0%")&" × "&N(Settings!$D$51)&" fill(s)") -> Step 7 (not used) | C40: L | D40: =IF(OR(JobType<>"Chemical Cleaning",Settings!$C$51=""),0,D28*1000*Settings!$C$51*IF(N(Settings!$D$51)=0,1,Settings!$D$51)) -> 0 | E40: =IF(OR(JobType<>"Chemical Cleaning",Settings!$C$51=""),0,E28*1000*Settings!$C$51*IF(N(Settings!$D$51)=0,1,Settings!$D$51)) -> 0 | F40: =IF(OR(JobType<>"Chemical Cleaning",Settings!$C$51=""),0,F28*1000*Settings!$C$51*IF(N(Settings!$D$51)=0,1,Settings!$D$51)) -> 0 | G40: =IF(OR(JobType<>"Chemical Cleaning",Settings!$C$51=""),0,G28*1000*Settings!$C$51*IF(N(Settings!$D$51)=0,1,Settings!$D$51)) -> 0 | H40: =IF(OR(JobType<>"Chemical Cleaning",Settings!$C$51=""),0,H28*1000*Settings!$C$51*IF(N(Settings!$D$51)=0,1,Settings!$D$51)) -> 0 | I40: =SUM(D40:H40) -> 0
B41: =IF(Settings!$B$52="","Step 8 (not used)",Settings!$B$52&" @ "&TEXT(Settings!$C$52,"0.0%")&" × "&N(Settings!$D$52)&" fill(s)") -> Step 8 (not used) | C41: L | D41: =IF(OR(JobType<>"Chemical Cleaning",Settings!$C$52=""),0,D28*1000*Settings!$C$52*IF(N(Settings!$D$52)=0,1,Settings!$D$52)) -> 0 | E41: =IF(OR(JobType<>"Chemical Cleaning",Settings!$C$52=""),0,E28*1000*Settings!$C$52*IF(N(Settings!$D$52)=0,1,Settings!$D$52)) -> 0 | F41: =IF(OR(JobType<>"Chemical Cleaning",Settings!$C$52=""),0,F28*1000*Settings!$C$52*IF(N(Settings!$D$52)=0,1,Settings!$D$52)) -> 0 | G41: =IF(OR(JobType<>"Chemical Cleaning",Settings!$C$52=""),0,G28*1000*Settings!$C$52*IF(N(Settings!$D$52)=0,1,Settings!$D$52)) -> 0 | H41: =IF(OR(JobType<>"Chemical Cleaning",Settings!$C$52=""),0,H28*1000*Settings!$C$52*IF(N(Settings!$D$52)=0,1,Settings!$D$52)) -> 0 | I41: =SUM(D41:H41) -> 0
B42: TOTAL CHEMICAL – chemical cleaning | C42: L | D42: =SUM(D34:D41) -> 528.83757 | E42: =SUM(E34:E41) -> 0 | F42: =SUM(F34:F41) -> 0 | G42: =SUM(G34:G41) -> 0 | H42: =SUM(H34:H41) -> 0 | I42: =SUM(D42:H42) -> 528.83757
B44: 3B. DECONTAMINATION – chemical (= considered volume × chemical % per equipment type)
...

Sheet Lookup
A1: Lookup tables used by the template (edit with care)
A3: Length units | D3: Volume units | G3: Weight units | J3: Head types | N3: Tube layout | Q3: Volume basis | S3: Job type
A4: Unit | B4: × to m | D4: Unit | E4: × to m³ | G4: Unit | H4: × to kg | J4: Head type | K4: k (V = k·D³) | L4: Formula | N4: Layout | O4: Area factor (× pitch²) | Q4: Basis | S4: Job type
A5: mm | B5: 0.001 | D5: m³ | E5: 1 | G5: kg | H5: 1 | J5: None / Open | K5: 0 | L5: No head volume | N5: Triangular (30°) | O5: =SQRT(3)/2 -> 0.8660254 | Q5: Dimensions | S5: Chemical Cleaning
A6: cm | B6: 0.01 | D6: L | E6: 0.001 | G6: t | H6: 1000 | J6: Flat | K6: 0 | L6: Flat cover / blind – no extra volume | N6: Rotated triangular (60°) | O6: =SQRT(3)/2 -> 0.8660254 | Q6: Water weight | S6: Decontamination
A7: m | B7: 1 | D7: US gal | E7: 0.0037854118 | G7: lb | H7: 0.45359237 | J7: 2:1 Ellipsoidal | K7: =PI()/24 -> 0.13089969 | L7: V = π/24 × D³ | N7: Square (90°) | O7: 1
A8: in | B8: 0.0254 | D8: Imp gal | E8: 0.00454609 | J8: Hemispherical | K8: =PI()/12 -> 0.26179939 | L8: V = π/12 × D³ | N8: Rotated square (45°) | O8: 1
A9: ft | B9: 0.3048 | D9: bbl | E9: 0.15898729 | J9: Torispherical (F&D) | K9: 0.0809 | L9: ASME flanged & dished, V ≈ 0.0809 × D³
D10: ft³ | E10: 0.028316847 | J10: Conical | K10: 0 | L10: V = π/12 × D² × cone height (enter cone height)
A14: Pipe wall thickness (mm) – ASME B36.10M / B36.19M. Verify against the project piping class; blank = schedule not standard for that size.
A15: NPS | B15: OD (mm) | C15: Sch 5S | D15: Sch 10S | E15: Sch 10 | F15: Sch 20 | G15: Sch 30 | H15: Sch 40 | I15: STD | J15: Sch 40S | K15: Sch 60 | L15: Sch 80 | M15: XS | N15: Sch 80S | O15: Sch 100 | P15: Sch 120 | Q15: Sch 140 | R15: Sch 160 | S15: XXS
A16: 1/2" (DN 15) | B16: 21.3 | C16: 1.65 | D16: 2.11 | H16: 2.77 | I16: 2.77 | J16: 2.77 | L16: 3.73 | M16: 3.73 | N16: 3.73 | R16: 4.78 | S16: 7.47
A17: 3/4" (DN 20) | B17: 26.7 | C17: 1.65 | D17: 2.11 | H17: 2.87 | I17: 2.87 | J17: 2.87 | L17: 3.91 | M17: 3.91 | N17: 3.91 | R17: 5.56 | S17: 7.82
A18: 1" (DN 25) | B18: 33.4 | C18: 1.65 | D18: 2.77 | H18: 3.38 | I18: 3.38 | J18: 3.38 | L18: 4.55 | M18: 4.55 | N18: 4.55 | R18: 6.35 | S18: 9.09
A19: 1-1/4" (DN 32) | B19: 42.2 | C19: 1.65 | D19: 2.77 | H19: 3.56 | I19: 3.56 | J19: 3.56 | L19: 4.85 | M19: 4.85 | N19: 4.85 | R19: 6.35 | S19: 9.7
A20: 1-1/2" (DN 40) | B20: 48.3 | C20: 1.65 | D20: 2.77 | H20: 3.68 | I20: 3.68 | J20: 3.68 | L20: 5.08 | M20: 5.08 | N20: 5.08 | R20: 7.14 | S20: 10.15
A21: 2" (DN 50) | B21: 60.3 | C21: 1.65 | D21: 2.77 | H21: 3.91 | I21: 3.91 | J21: 3.91 | L21: 5.54 | M21: 5.54 | N21: 5.54 | R21: 8.74 | S21: 11.07
A22: 2-1/2" (DN 65) | B22: 73 | C22: 2.11 | D22: 3.05 | H22: 5.16 | I22: 5.16 | J22: 5.16 | L22: 7.01 | M22: 7.01 | N22: 7.01 | R22: 9.53 | S22: 14.02
A23: 3" (DN 80) | B23: 88.9 | C23: 2.11 | D23: 3.05 | H23: 5.49 | I23: 5.49 | J23: 5.49 | L23: 7.62 | M23: 7.62 | N23: 7.62 | R23: 11.13 | S23: 15.24
A24: 4" (DN 100) | B24: 114.3 | C24: 2.11 | D24: 3.05 | H24: 6.02 | I24: 6.02 | J24: 6.02 | L24: 8.56 | M24: 8.56 | N24: 8.56 | P24: 11.13 | R24: 13.49 | S24: 17.12
A25: 5" (DN 125) | B25: 141.3 | C25: 2.77 | D25: 3.4 | H25: 6.55 | I25: 6.55 | J25: 6.55 | L25: 9.53 | M25: 9.53 | N25: 9.53 | P25: 12.7 | R25: 15.88 | S25: 19.05
A26: 6" (DN 150) | B26: 168.3 | C26: 2.77 | D26: 3.4 | H26: 7.11 | I26: 7.11 | J26: 7.11 | L26: 10.97 | M26: 10.97 | N26: 10.97 | P26: 14.27 | R26: 18.26 | S26: 21.95
A27: 8" (DN 200) | B27: 219.1 | C27: 2.77 | D27: 3.76 | F27: 6.35 | G27: 7.04 | H27: 8.18 | I27: 8.18 | J27: 8.18 | K27: 10.31 | L27: 12.7 | M27: 12.7 | N27: 12.7 | O27: 15.09 | P27: 18.26 | Q27: 20.62 | R27: 23.01 | S27: 22.23
A28: 10" (DN 250) | B28: 273 | C28: 3.4 | D28: 4.19 | F28: 6.35 | G28: 7.8 | H28: 9.27 | I28: 9.27 | J28: 9.27 | K28: 12.7 | L28: 15.09 | M28: 12.7 | N28: 12.7 | O28: 18.26 | P28: 21.44 | Q28: 25.4 | R28: 28.58 | S28: 25.4
A29: 12" (DN 300) | B29: 323.8 | C29: 3.96 | D29: 4.57 | F29: 6.35 | G29: 8.38 | H29: 10.31 | I29: 9.53 | J29: 9.53 | K29: 14.27 | L29: 17.48 | M29: 12.7 | N29: 12.7 | O29: 21.44 | P29: 25.4 | Q29: 28.58 | R29: 33.32 | S29: 25.4
A30: 14" (DN 350) | B30: 355.6 | C30: 3.96 | D30: 4.78 | E30: 6.35 | F30: 7.92 | G30: 9.53 | H30: 11.13 | I30: 9.53 | K30: 15.09 | L30: 19.05 | M30: 12.7 | O30: 23.83 | P30: 27.79 | Q30: 31.75 | R30: 35.71
A31: 16" (DN 400) | B31: 406.4 | C31: 4.19 | D31: 4.78 | E31: 6.35 | F31: 7.92 | G31: 9.53 | H31: 12.7 | I31: 9.53 | K31: 16.66 | L31: 21.44 | M31: 12.7 | O31: 26.19 | P31: 30.96 | Q31: 36.53 | R31: 40.49
A32: 18" (DN 450) | B32: 457 | C32: 4.19 | D32: 4.78 | E32: 6.35 | F32: 7.92 | G32: 11.13 | H32: 14.27 | I32: 9.53 | K32: 19.05 | L32: 23.83 | M32: 12.7 | O32: 29.36 | P32: 34.93 | Q32: 39.67 | R32: 45.24
A33: 20" (DN 500) | B33: 508 | C33: 4.78 | D33: 5.54 | E33: 6.35 | F33: 9.53 | G33: 12.7 | H33: 15.09 | I33: 9.53 | K33: 20.62 | L33: 26.19 | M33: 12.7 | O33: 32.54 | P33: 38.1 | Q33: 44.45 | R33: 50.01
A34: 24" (DN 600) | B34: 610 | C34: 5.54 | D34: 6.35 | E34: 6.35 | F34: 9.53 | G34: 14.27 | H34: 17.48 | I34: 9.53 | K34: 24.61 | L34: 30.96 | M34: 12.7 | O34: 38.89 | P34: 46.02 | Q34: 52.37 | R34: 59.54
A35: 30" (DN 750) | B35: 762 | C35: 6.35 | D35: 7.92 | E35: 7.92 | F35: 12.7 | G35: 15.88 | I35: 9.53 | M35: 12.7
A36: 36" (DN 900) | B36: 914 | E36: 7.92 | F36: 12.7 | G36: 15.88 | H36: 19.05 | I36: 9.53 | M36: 12.7
