Workbook

Sheet Quote Info
B1: DELIGHT INTERNATIONAL – PRICING: QUOTE INFORMATION
B2: Fill in this sheet first. Yellow = input (blue text) · green = calculated. Markups, contingency, discount and VAT apply to every service in this workbook.
B4: QUOTATION DETAILS
B5: Quotation No.
B6: Revision
B7: Date
B8: Client
B9: Attention (client contact)
B10: Project / Plant
B11: Location / site
B12: Client enquiry / RFQ reference
B13: Prepared by
B15: CURRENCY (rates are entered in AED; the client quote is converted)
B16: Quote currency | C16: AED
B17: Currency | C17: AED per 1 unit | F17: Source
B18: AED | C18: 1 | F18: Base currency
B19: USD | C19: 3.6725 | F19: UAE central bank peg (AED 3.6725 = USD 1)
B20: SAR | C20: =3.6725/3.75 -> 0.97933333 | F20: Via USD pegs (SAR 3.75 = USD 1)
B21: OMR | C21: =3.6725/0.3845 -> 9.5513654 | F21: Via USD pegs (OMR 0.3845 = USD 1)
B22: GBP | C22: 4.92 | F22: DUQM Rev 1.0 market rate 17-Jun-2026 – update
B23: Exchange rate used (AED per 1 quote-currency unit) | C23: =INDEX(CurrRate,MATCH(QCurr,CurrU,0)) -> 1
B25: WORKING PATTERN
B26: Shift length (hours) | C26: 12 | G26: Manpower rates are per person per shift (12-hour day)
B27: Shifts per day (1 = day only, 2 = 24-hour) | C27: 2
B29: MARKUP CONTROLS (selling = cost × (1 + markup))
B30: Markup mode | C30: Simple | E30: Simple | F30: Detailed | G30: Simple = 2 markups (in-house / rented). Detailed = 5 markups.
B31: SIMPLE – In-house crew & equipment | C31: 0.3 | G31: 30% = highest of ASAB R2 (30%) and DUQM Rev 1.0 (10–30%) – edit per job
B32: SIMPLE – Rented crew & equipment, bought-in items | C32: 0.3
B33: DETAILED – In-house manpower | C33: 0.3
B34: DETAILED – Rented manpower | C34: 0.3
B35: DETAILED – In-house equipment | C35: 0.3
B36: DETAILED – Rented equipment | C36: 0.3
B37: DETAILED – Chemicals, consumables & third-party services | C37: 0.3
B39: Effective markup applied (calculated) | C39: In-house | D39: Rented | E39: Third-party
B40: Manpower | C40: =IF(QMkMode="Detailed",N(MkInMP),N(MkIn)) -> 0.3 | D40: =IF(QMkMode="Detailed",N(MkRentMP),N(MkRent)) -> 0.3 | E40: =IF(QMkMode="Detailed",N(MkCons),N(MkRent)) -> 0.3
B41: Equipment | C41: =IF(QMkMode="Detailed",N(MkInEq),N(MkIn)) -> 0.3 | D41: =IF(QMkMode="Detailed",N(MkRentEq),N(MkRent)) -> 0.3 | E41: =IF(QMkMode="Detailed",N(MkCons),N(MkRent)) -> 0.3
B42: Chemicals, consumables & services | C42: =IF(QMkMode="Detailed",N(MkCons),N(MkIn)) -> 0.3 | D42: =IF(QMkMode="Detailed",N(MkCons),N(MkRent)) -> 0.3 | E42: =IF(QMkMode="Detailed",N(MkCons),N(MkRent)) -> 0.3
B44: CONTINGENCY, DISCOUNT & VAT
B45: Contingency (% of total cost, internal risk allowance) | G45: Added to the price, not marked up
B46: Commercial discount (% of price) | G46: Applied to the price before VAT
...

Sheet Rates
B1: RATES (COST, AED, excl. markup)
B2: Values taken from ASAB CC Pricing R2 and DUQM Pricing Rev 1.0 – the higher one where both list the same item. Rented column blank = same as cost. Add items in the blank yellow rows.
B4: MANPOWER – cost per person per shift / day
B5: Grade | D5: Cost | E5: Rented cost (if different) | H5: Source / remarks
B6: Project Manager | D6: 1000 | H6: ASAB 1,000 · DUQM 1,000
B7: Project Engineer | D7: 700 | H7: ASAB 500 · DUQM 700 → highest
B8: Supervisor | D8: 500 | H8: ASAB 400 · DUQM 500 → highest
B9: Job Performer / Permit Receiver | H9: not in either sheet
B10: Safety Officer | D10: 300 | H10: DUQM
B11: Technician / Operator | D11: 400 | H11: ASAB 300 · DUQM 400 → highest
B12: Pipe Fitter | H12: not in either sheet
B13: Helper | D13: 300 | H13: ASAB 200 · DUQM 300 → highest
B14: Others | D14: 400 | H14: DUQM
B15: Decontamination Specialist | D15: 5400 | H15: DUQM (per day)
B16: Specialised Services | D16: 2400 | H16: DUQM (per day)
B17: Remote Technical Support | D17: 2250 | H17: DUQM (per day)
B25: EQUIPMENT – cost per unit per day (LS = lump sum, counted once)
B26: Equipment | C26: Unit | D26: Cost | E26: Rented cost (if different) | H26: Source / remarks
B27: Chemical circulation pump skid (SS316, VFD) | C27: day | D27: 800 | H27: ASAB
B28: Vessel circulation pump (gamma jet feed) | C28: day | D28: 800 | H28: ASAB
B29: Centrifugal pump | C29: day | D29: 1000 | H29: DUQM
B30: Drum pump | C30: day | D30: 500 | H30: DUQM
B31: Diaphragm pump & manifolds (transfer set) | C31: day | D31: 300 | H31: ASAB
B32: Diaphragm pump | C32: day | D32: 100 | H32: DUQM
B33: Manifold | C33: day | D33: 250 | H33: DUQM
B34: Chemical mixing / dosing tank 10 m³ | C34: day | D34: 150 | H34: ASAB
B35: DM water buffer tank | C35: day | D35: 150 | H35: ASAB
B36: Waste holding tank 500 bbl (~80 m³) | C36: day | D36: 400 | H36: ASAB rental
B37: Effluent tank 60 m³ | C37: day | D37: 500 | H37: DUQM
B38: Diesel boiler 2 TPH | C38: day | D38: 3000 | H38: ASAB rental
... B53: 10-point VP injection module (CORE) | C53: day | D53: 890 | H53: DUQM
B65: CHEMICALS – price per kg (or per IBC)
B66: Chemical | C66: Purity | D66: Price per kg | E66: Price per IBC | F66: IBC net content (kg) | G66: Price per kg used | H66: Source / remarks
B67: SODIUM HYDROXIDE (CAUSTIC SODA) | C67: 0.49 | D67: 3 | G67: =IF(ISNUMBER(D67),D67,IF(AND(ISNUMBER(E67),N(F67)>0),E67/F67,"")) -> 3 | H67: ASAB R2
B68: CITRIC ACID | C68: 1 | D68: 4 | G68: =IF(ISNUMBER(D68),D68,IF(AND(ISNUMBER(E68),N(F68)>0),E68/F68,"")) -> 4 | H68: ASAB R2
B69: AMMONIUM BIFLUORIDE | C69: 1 | D69: 16 | G69: =IF(ISNUMBER(D69),D69,IF(AND(ISNUMBER(E69),N(F69)>0),E69/F69,"")) -> 16 | H69: ASAB R2
B70: SODIUM META SILICATE | C70: 1 | D70: 9 | G70: =IF(ISNUMBER(D70),D70,IF(AND(ISNUMBER(E70),N(F70)>0),E70/F70,"")) -> 9 | H70: ASAB R2
B71: TRI SODIUM PHOSPHATE | C71: 1 | D71: 6 | G71: =IF(ISNUMBER(D71),D71,IF(AND(ISNUMBER(E71),N(F71)>0),E71/F71,"")) -> 6 | H71: ASAB R2
B72: INHIBITORS - RODINE & ARMOHIB | C72: 1 | D72: 12 | G72: =IF(ISNUMBER(D72),D72,IF(AND(ISNUMBER(E72),N(F72)>0),E72/F72,"")) -> 12 | H72: ASAB R2
B73: SURFACTANTS - NP-9 / MULTI CLEAN | C73: 1 | D73: 12 | G73: =IF(ISNUMBER(D73),D73,IF(AND(ISNUMBER(E73),N(F73)>0),E73/F73,"")) -> 12 | H73: ASAB R2
...

Sheet CC Settings
B1: VOLUME SETTINGS
B2: Yellow = input. Unit names, loop names and regime names feed the drop-down lists on the volume sheet.
B4: PROJECT
B5: Client | C5: =QClient -> 0
B6: Plant / Project | C6: =QProject -> 0
B7: Proposal No. | C7: =QNo -> 0
B9: Job type | C9: Chemical Cleaning | D9: Fixed for this service
B11: GENERAL
B12: Water density (water weight → volume) | C12: 1000 | D12: kg/m³
B13: Tube pitch ratio (pitch ÷ OD) | C13: 1.25 | D13: –
B14: Default circulation / solution allowance | C14: 1.15 | D14: × fill volume | F14: Solution = equipment volume × fill % × circulation (ASAB: 115%)
B15: Default no. of fills (for waste volume) | C15: 5 | D15: fills
B16: Default waste allowance | C16: 0.25 | D16: on top of fills | F16: Waste = solution × fills × (1 + allowance) (ASAB: 5 fills + 25%)
B18: DEFAULT FILL % BY EQUIPMENT TYPE (used when the Fill % cell on a row is blank)
B19: Equipment type | C19: Chemical cleaning | D19: Decontamination | F19: Method note
B20: Exchanger | C20: 1 | D20: 1 | F20: CC full volume · Decon vapour phase
B21: Piping | C21: 1 | D21: 1 | F21: CC full volume · Decon vapour phase
B22: Column | C22: 0.2 | D22: 1 | F22: CC 20% + gamma jet · Decon vapour phase (complete volume)
B23: Vessel – Vertical | C23: 0.2 | D23: 0.3 | F23: CC 20% + gamma jet · Decon boil-out 30%
B24: Vessel – Horizontal | C24: 0.2 | D24: 0.3 | F24: CC 20% + gamma jet · Decon boil-out 30%
B25: Tank | C25: 0.2 | D25: 0.3 | F25: CC 20% + gamma jet · Decon gamma-jet circulation (TO CONFIRM)
B26: Filter / Other | C26: 0.2 | D26: 0.3 | F26: CC 20% + gamma jet · Decon boil-out 30%
B27: ASAB R2 used 15% fill for vessels with gamma jetting – set per project.
B29: UNITS / TRAINS (up to 12)
B30: Unit 1 name | C30: Unit 1
B31: Unit 2 name | C31: Unit 2
B32: Unit 3 name | C32: Unit 3
B33: Unit 4 name | C33: Unit 4
B34: Unit 5 name | C34: Unit 5
B35: Unit 6 name | C35: Unit 6
B36: Unit 7 name | C36: Unit 7
B37: Unit 8 name | C37: Unit 8
B38: Unit 9 name | C38: Unit 9
B39: Unit 10 name | C39: Unit 10
B40: Unit 11 name | C40: Unit 11
B41: Unit 12 name | C41: Unit 12
B43: CHEMICAL REGIMES (up to 4; concentrations on the chemicals sheet)
B44: Regime 1 name | C44: SS
B45: Regime 2 name | C45: CS
B46: Regime 3 name | C46: Regime 3
...

Sheet CC Volume
A1: VOLUME CALCULATION – one row per equipment, units stacked
A2: ="Job type: "&CC_JobType&" · Client: "&CC_Client&" · Plant: "&CC_Plant&" · Proposal: "&CC_ProjNo -> Job type: Chemical Cleaning · Client: 0 · Plant: 0 · Proposal: 0
A3: Yellow = input (only the columns that apply to the equipment type). Units of each dimension column are chosen in row 7. Factors left blank use the defaults on the settings sheet. Volumes in m³.
A5: ITEM | J5: PIPING | N5: SHELL / VESSEL | S5: TUBES (exchangers) | Y5: CHANNELS / BONNETS | AD5: CALCULATED (m³) | AI5: FACTORS (blank = default) | AM5: RESULT (m³)
A6: # | B6: Loop | C6: Tag No. | D6: Description / service | E6: Equipment type | F6: Chemical regime | G6: Volume basis | H6: Given volume | I6: Water weight | J6: NPS | K6: Schedule | L6: Pipe ID (if given) | M6: Pipe length | N6: Shell / vessel ID | O6: Length T/T | P6: Head 1 / shell cover | Q6: Head 2 | R6: Cone height | S6: No. of tubes | T6: Tube OD | U6: Tube ID | V6: Tube length | W6: Tube pitch | X6: Tube layout | Y6: Channel / bonnet ID | Z6: Front channel length | AA6: Front head | AB6: Rear channel length | AC6: Rear head | AD6: Tube side vol. | AE6: Shell side / vessel vol. | AF6: Piping vol. | AG6: Volume from dimensions | AH6: Volume from water weight | AI6: Fill % | AJ6: Circulation % | AK6: No. of fills | AL6: Waste allowance % | AM6: WASTE VOLUME | AN6: EQUIPMENT VOLUME | AO6: SOLUTION VOLUME | AP6: OD used (m) | AQ6: Shell area (m²) | AR6: Shell length (m) | AS6: Pipe ID used (mm) | AT6: Fill used | AU6: Unit no.
H7: m³ | I7: kg | L7: mm | M7: m | N7: mm | O7: mm | R7: mm | S7: nos | T7: mm | U7: mm | V7: mm | W7: mm | Y7: mm | Z7: mm | AB7: mm | AD7: m³ | AE7: m³ | AF7: m³ | AG7: m³ | AH7: m³ | AI7: % | AJ7: % | AK7: nos | AL7: % | AM7: m³ | AN7: m³ | AO7: m³
A9: ="UNIT 1: "&INDEX(CC_UnitNames,1) -> UNIT 1: Unit 1
A10: 1 | B10: Loop 1 | C10: EXAMPLE ML-1 | D10: Piping loop – volume given (ASAB ML-1) | E10: Piping | F10: SS | G10: Given volume | H10: 27.115 | AD10: =IF(E10="Exchanger",IF(AND(ISNUMBER(S10),ISNUMBER(U10),ISNUMBER(V10)),S10*PI()/4*(U10*INDEX(LenF,MATCH($U$7,LenU,0)))^2*V10*INDEX(LenF,MATCH($V$7,LenU,0)),0)+IF(ISNUMBER(Y10),PI()/4*(Y10*INDEX(LenF,MATCH($Y$7,LenU,0)))^2*N(Z10)*INDEX(LenF,MATCH($Z$7,LenU,0))+IF(AA10="",0,IF(AA10="Conical",PI()/12*(Y10*INDEX(LenF,MATCH($Y$7,LenU,0)))^2*(0),INDEX(HeadK,MATCH(AA10,HeadU,0))*(Y10*INDEX(LenF,MATCH($Y$7,LenU,0)))^3)),0)+IF(ISNUMBER(Y10),PI()/4*(Y10*INDEX(LenF,MATCH($Y$7,LenU,0)))^2*N(AB10)*INDEX(LenF,MATCH($AB$7,LenU,0))+IF(AC10="",0,IF(AC10="Conical",PI()/12*(Y10*INDEX(LenF,MATCH($Y$7,LenU,0)))^2*(0),INDEX(HeadK,MATCH(AC10,HeadU,0))*(Y10*INDEX(LenF,MATCH($Y$7,LenU,0)))^3)),0),"") | AE10: =IF(OR(E10="",E10="Piping"),"",IF(E10="Exchanger",AQ10*AR10+IF(P10="",0,IF(P10="Conical",PI()/12*(SQRT(4*AQ10/PI()))^2*(0),INDEX(HeadK,MATCH(P10,HeadU,0))*(SQRT(4*AQ10/PI()))^3))-IF(AND(ISNUMBER(S10),ISNUMBER(V10)),S10*PI()/4*AP10^2*V10*INDEX(LenF,MATCH($V$7,LenU,0)),0),IF(ISNUMBER(N10),PI()/4*(N10*INDEX(LenF,MATCH($N$7,LenU,0)))^2*N(O10)*INDEX(LenF,MATCH($O$7,LenU,0))+IF(P10="",0,IF(P10="Conical",PI()/12*(N10*INDEX(LenF,MATCH($N$7,LenU,0)))^2*(N(R10)*INDEX(LenF,MATCH($R$7,LenU,0))),INDEX(HeadK,MATCH(P10,HeadU,0))*(N10*INDEX(LenF,MATCH($N$7,LenU,0)))^3))+IF(Q10="",0,IF(Q10="Conical",PI()/12*(N10*INDEX(LenF,MATCH($N$7,LenU,0)))^2*(N(R10)*INDEX(LenF,MATCH($R$7,LenU,0))),INDEX(HeadK,MATCH(Q10,HeadU,0))*(N10*INDEX(LenF,MATCH($N$7,LenU,0)))^3)),0))) | AF10: =IF(E10<>"Piping","",IF(AND(ISNUMBER(AS10),ISNUMBER(M10)),PI()/4*(AS10/1000)^2*M10*INDEX(LenF,MATCH($M$7,LenU,0)),0)) -> 0 | AG10: =IF(E10="","",N(AD10)+N(AE10)+N(AF10)) -> 0 | AH10: =IF(ISNUMBER(I10),I10*INDEX(WtF,MATCH($I$7,WtU,0))/CC_WaterRho,"") | AM10: =IF(AO10="","",AO10*IF(ISNUMBER(AK10),AK10,CC_DefFills)*(1+IF(ISNUMBER(AL10),AL10,CC_DefAllow))) -> 194.88906 | AN10: =IF(G10="Given volume",IF(ISNUMBER(H10),H10*INDEX(VolF,MATCH($H$7,VolU,0)),""),IF(G10="Water weight",AH10,IF(N(AG10)=0,"",AG10))) -> 27.115 | AO10: =IF(N(AN10)=0,"",AN10*AT10*IF(ISNUMBER(AJ10),AJ10,CC_DefCirc)) -> 31.18225 | AP10: =IF(ISNUMBER(T10),T10*INDEX(LenF,MATCH($T$7,LenU,0)),IF(ISNUMBER(W10),W10*INDEX(LenF,MATCH($W$7,LenU,0))/CC_PitchRatio,0)) -> 0 | AQ10: =IF(ISNUMBER(N10),PI()/4*(N10*INDEX(LenF,MATCH($N$7,LenU,0)))^2,IF(AND(ISNUMBER(S10),ISNUMBER(W10),X10<>""),S10*(W10*INDEX(LenF,MATCH($W$7,LenU,0)))^2*INDEX(LayoutF,MATCH(X10,LayoutU,0)),0)) -> 0 | AR10: =IF(ISNUMBER(O10),O10*INDEX(LenF,MATCH($O$7,LenU,0)),IF(ISNUMBER(V10),V10*INDEX(LenF,MATCH($V$7,LenU,0)),0)) -> 0 | AS10: =IF(ISNUMBER(L10),L10*INDEX(LenF,MATCH($L$7,LenU,0))*1000,IF(OR(J10="",K10=""),"",IFERROR(IF(INDEX(PipeWT,MATCH(J10,NPSU,0),MATCH(K10,SchU,0))="","Sch n/a",INDEX(PipeOD,MATCH(J10,NPSU,0))-2*INDEX(PipeWT,MATCH(J10,NPSU,0),MATCH(K10,SchU,0))),""))) | AT10: =IF(ISNUMBER(AI10),AI10,IFERROR(INDEX(IF(CC_JobType="Decontamination",CC_TypeFillDC,CC_TypeFillCC),MATCH(E10,CC_TypeL,0)),1)) -> 1 | AU10: 1
A11: 2 | B11: Loop 2 | C11: EXAMPLE V-101 | D11: Vertical vessel (dimensions) | E11: Vessel – Vertical | F11: SS | N11: 2000 | O11: 6000 | P11: 2:1 Ellipsoidal | Q11: 2:1 Ellipsoidal | AD11: =IF(E11="Exchanger",IF(AND(ISNUMBER(S11),ISNUMBER(U11),ISNUMBER(V11)),S11*PI()/4*(U11*INDEX(LenF,MATCH($U$7,LenU,0)))^2*V11*INDEX(LenF,MATCH($V$7,LenU,0)),0)+IF(ISNUMBER(Y11),PI()/4*(Y11*INDEX(LenF,MATCH($Y$7,LenU,0)))^2*N(Z11)*INDEX(LenF,MATCH($Z$7,LenU,0))+IF(AA11="",0,IF(AA11="Conical",PI()/12*(Y11*INDEX(LenF,MATCH($Y$7,LenU,0)))^2*(0),INDEX(HeadK,MATCH(AA11,HeadU,0))*(Y11*INDEX(LenF,MATCH($Y$7,LenU,0)))^3)),0)+IF(ISNUMBER(Y11),PI()/4*(Y11*INDEX(LenF,MATCH($Y$7,LenU,0)))^2*N(AB11)*INDEX(LenF,MATCH($AB$7,LenU,0))+IF(AC11="",0,IF(AC11="Conical",PI()/12*(Y11*INDEX(LenF,MATCH($Y$7,LenU,0)))^2*(0),INDEX(HeadK,MATCH(AC11,HeadU,0))*(Y11*INDEX(LenF,MATCH($Y$7,LenU,0)))^3)),0),"") | AE11: =IF(OR(E11="",E11="Piping"),"",IF(E11="Exchanger",AQ11*AR11+IF(P11="",0,IF(P11="Conical",PI()/12*(SQRT(4*AQ11/PI()))^2*(0),INDEX(HeadK,MATCH(P11,HeadU,0))*(SQRT(4*AQ11/PI()))^3))-IF(AND(ISNUMBER(S11),ISNUMBER(V11)),S11*PI()/4*AP11^2*V11*INDEX(LenF,MATCH($V$7,LenU,0)),0),IF(ISNUMBER(N11),PI()/4*(N11*INDEX(LenF,MATCH($N$7,LenU,0)))^2*N(O11)*INDEX(LenF,MATCH($O$7,LenU,0))+IF(P11="",0,IF(P11="Conical",PI()/12*(N11*INDEX(LenF,MATCH($N$7,LenU,0)))^2*(N(R11)*INDEX(LenF,MATCH($R$7,LenU,0))),INDEX(HeadK,MATCH(P11,HeadU,0))*(N11*INDEX(LenF,MATCH($N$7,LenU,0)))^3))+IF(Q11="",0,IF(Q11="Conical",PI()/12*(N11*INDEX(LenF,MATCH($N$7,LenU,0)))^2*(N(R11)*INDEX(LenF,MATCH($R$7,LenU,0))),INDEX(HeadK,MATCH(Q11,HeadU,0))*(N11*INDEX(LenF,MATCH($N$7,LenU,0)))^3)),0))) -> 20.943951 | AF11: =IF(E11<>"Piping","",IF(AND(ISNUMBER(AS11),ISNUMBER(M11)),PI()/4*(AS11/1000)^2*M11*INDEX(LenF,MATCH($M$7,LenU,0)),0)) | AG11: =IF(E11="","",N(AD11)+N(AE11)+N(AF11)) -> 20.943951 | AH11: =IF(ISNUMBER(I11),I11*INDEX(WtF,MATCH($I$7,WtU,0))/CC_WaterRho,"") | AI11: 0.15 | AM11: =IF(AO11="","",AO11*IF(ISNUMBER(AK11),AK11,CC_DefFills)*(1+IF(ISNUMBER(AL11),AL11,CC_DefAllow))) -> 22.580197 | AN11: =IF(G11="Given volume",IF(ISNUMBER(H11),H11*INDEX(VolF,MATCH($H$7,VolU,0)),""),IF(G11="Water weight",AH11,IF(N(AG11)=0,"",AG11))) -> 20.943951 | AO11: =IF(N(AN11)=0,"",AN11*AT11*IF(ISNUMBER(AJ11),AJ11,CC_DefCirc)) -> 3.6128316 | AP11: =IF(ISNUMBER(T11),T11*INDEX(LenF,MATCH($T$7,LenU,0)),IF(ISNUMBER(W11),W11*INDEX(LenF,MATCH($W$7,LenU,0))/CC_PitchRatio,0)) -> 0 | AQ11: =IF(ISNUMBER(N11),PI()/4*(N11*INDEX(LenF,MATCH($N$7,LenU,0)))^2,IF(AND(ISNUMBER(S11),ISNUMBER(W11),X11<>""),S11*(W11*INDEX(LenF,MATCH($W$7,LenU,0)))^2*INDEX(LayoutF,MATCH(X11,LayoutU,0)),0)) -> 3.1415927 | AR11: =IF(ISNUMBER(O11),O11*INDEX(LenF,MATCH($O$7,LenU,0)),IF(ISNUMBER(V11),V11*INDEX(LenF,MATCH($V$7,LenU,0)),0)) -> 6 | AS11: =IF(ISNUMBER(L11),L11*INDEX(LenF,MATCH($L$7,LenU,0))*1000,IF(OR(J11="",K11=""),"",IFERROR(IF(INDEX(PipeWT,MATCH(J11,NPSU,0),MATCH(K11,SchU,0))="","Sch n/a",INDEX(PipeOD,MATCH(J11,NPSU,0))-2*INDEX(PipeWT,MATCH(J11,NPSU,0),MATCH(K11,SchU,0))),""))) | AT11: =IF(ISNUMBER(AI11),AI11,IFERROR(INDEX(IF(CC_JobType="Decontamination",CC_TypeFillDC,CC_TypeFillCC),MATCH(E11,CC_TypeL,0)),1)) -> 0.15 | AU11: 1
A12: 3 | B12: Loop 2 | C12: EXAMPLE E-101 | D12: Shell & tube exchanger | E12: Exchanger | F12: SS | N12: 800 | O12: 6000 | S12: 500 | T12: 19.05 | U12: 15.75 | V12: 6096 | W12: 23.81 | X12: Triangular (30°) | Y12: 800 | Z12: 600 | AA12: Flat | AB12: 300 | AC12: 2:1 Ellipsoidal | AD12: =IF(E12="Exchanger",IF(AND(ISNUMBER(S12),ISNUMBER(U12),ISNUMBER(V12)),S12*PI()/4*(U12*INDEX(LenF,MATCH($U$7,LenU,0)))^2*V12*INDEX(LenF,MATCH($V$7,LenU,0)),0)+IF(ISNUMBER(Y12),PI()/4*(Y12*INDEX(LenF,MATCH($Y$7,LenU,0)))^2*N(Z12)*INDEX(LenF,MATCH($Z$7,LenU,0))+IF(AA12="",0,IF(AA12="Conical",PI()/12*(Y12*INDEX(LenF,MATCH($Y$7,LenU,0)))^2*(0),INDEX(HeadK,MATCH(AA12,HeadU,0))*(Y12*INDEX(LenF,MATCH($Y$7,LenU,0)))^3)),0)+IF(ISNUMBER(Y12),PI()/4*(Y12*INDEX(LenF,MATCH($Y$7,LenU,0)))^2*N(AB12)*INDEX(LenF,MATCH($AB$7,LenU,0))+IF(AC12="",0,IF(AC12="Conical",PI()/12*(Y12*INDEX(LenF,MATCH($Y$7,LenU,0)))^2*(0),INDEX(HeadK,MATCH(AC12,HeadU,0))*(Y12*INDEX(LenF,MATCH($Y$7,LenU,0)))^3)),0),"") -> 1.1132452 | AE12: =IF(OR(E12="",E12="Piping"),"",IF(E12="Exchanger",AQ12*AR12+IF(P12="",0,IF(P12="Conical",PI()/12*(SQRT(4*AQ12/PI()))^2*(0),INDEX(HeadK,MATCH(P12,HeadU,0))*(SQRT(4*AQ12/PI()))^3))-IF(AND(ISNUMBER(S12),ISNUMBER(V12)),S12*PI()/4*AP12^2*V12*INDEX(LenF,MATCH($V$7,LenU,0)),0),IF(ISNUMBER(N12),PI()/4*(N12*INDEX(LenF,MATCH($N$7,LenU,0)))^2*N(O12)*INDEX(LenF,MATCH($O$7,LenU,0))+IF(P12="",0,IF(P12="Conical",PI()/12*(N12*INDEX(LenF,MATCH($N$7,LenU,0)))^2*(N(R12)*INDEX(LenF,MATCH($R$7,LenU,0))),INDEX(HeadK,MATCH(P12,HeadU,0))*(N12*INDEX(LenF,MATCH($N$7,LenU,0)))^3))+IF(Q12="",0,IF(Q12="Conical",PI()/12*(N12*INDEX(LenF,MATCH($N$7,LenU,0)))^2*(N(R12)*INDEX(LenF,MATCH($R$7,LenU,0))),INDEX(HeadK,MATCH(Q12,HeadU,0))*(N12*INDEX(LenF,MATCH($N$7,LenU,0)))^3)),0))) -> 2.147179 | AF12: =IF(E12<>"Piping","",IF(AND(ISNUMBER(AS12),ISNUMBER(M12)),PI()/4*(AS12/1000)^2*M12*INDEX(LenF,MATCH($M$7,LenU,0)),0)) | AG12: =IF(E12="","",N(AD12)+N(AE12)+N(AF12)) -> 3.2604242 | AH12: =IF(ISNUMBER(I12),I12*INDEX(WtF,MATCH($I$7,WtU,0))/CC_WaterRho,"") | AM12: =IF(AO12="","",AO12*IF(ISNUMBER(AK12),AK12,CC_DefFills)*(1+IF(ISNUMBER(AL12),AL12,CC_DefAllow))) -> 23.434299 | AN12: =IF(G12="Given volume",IF(ISNUMBER(H12),H12*INDEX(VolF,MATCH($H$7,VolU,0)),""),IF(G12="Water weight",AH12,IF(N(AG12)=0,"",AG12))) -> 3.2604242 | AO12: =IF(N(AN12)=0,"",AN12*AT12*IF(ISNUMBER(AJ12),AJ12,CC_DefCirc)) -> 3.7494878 | AP12: =IF(ISNUMBER(T12),T12*INDEX(LenF,MATCH($T$7,LenU,0)),IF(ISNUMBER(W12),W12*INDEX(LenF,MATCH($W$7,LenU,0))/CC_PitchRatio,0)) -> 0.01905 | AQ12: =IF(ISNUMBER(N12),PI()/4*(N12*INDEX(LenF,MATCH($N$7,LenU,0)))^2,IF(AND(ISNUMBER(S12),ISNUMBER(W12),X12<>""),S12*(W12*INDEX(LenF,MATCH($W$7,LenU,0)))^2*INDEX(LayoutF,MATCH(X12,LayoutU,0)),0)) -> 0.50265482 | AR12: =IF(ISNUMBER(O12),O12*INDEX(LenF,MATCH($O$7,LenU,0)),IF(ISNUMBER(V12),V12*INDEX(LenF,MATCH($V$7,LenU,0)),0)) -> 6 | AS12: =IF(ISNUMBER(L12),L12*INDEX(LenF,MATCH($L$7,LenU,0))*1000,IF(OR(J12="",K12=""),"",IFERROR(IF(INDEX(PipeWT,MATCH(J12,NPSU,0),MATCH(K12,SchU,0))="","Sch n/a",INDEX(PipeOD,MATCH(J12,NPSU,0))-2*INDEX(PipeWT,MATCH(J12,NPSU,0),MATCH(K12,SchU,0))),""))) | AT12: =IF(ISNUMBER(AI12),AI12,IFERROR(INDEX(IF(CC_JobType="Decontamination",CC_TypeFillDC,CC_TypeFillCC),MATCH(E12,CC_TypeL,0)),1)) -> 1 | AU12: 1
A13: 4 | C13: EXAMPLE 6"-P-1001 | D13: Line from isometric | E13: Piping | F13: CS | J13: 6" (DN 150) | K13: Sch 40 | M13: 120 | AD13: =IF(E13="Exchanger",IF(AND(ISNUMBER(S13),ISNUMBER(U13),ISNUMBER(V13)),S13*PI()/4*(U13*INDEX(LenF,MATCH($U$7,LenU,0)))^2*V13*INDEX(LenF,MATCH($V$7,LenU,0)),0)+IF(ISNUMBER(Y13),PI()/4*(Y13*INDEX(LenF,MATCH($Y$7,LenU,0)))^2*N(Z13)*INDEX(LenF,MATCH($Z$7,LenU,0))+IF(AA13="",0,IF(AA13="Conical",PI()/12*(Y13*INDEX(LenF,MATCH($Y$7,LenU,0)))^2*(0),INDEX(HeadK,MATCH(AA13,HeadU,0))*(Y13*INDEX(LenF,MATCH($Y$7,LenU,0)))^3)),0)+IF(ISNUMBER(Y13),PI()/4*(Y13*INDEX(LenF,MATCH($Y$7,LenU,0)))^2*N(AB13)*INDEX(LenF,MATCH($AB$7,LenU,0))+IF(AC13="",0,IF(AC13="Conical",PI()/12*(Y13*INDEX(LenF,MATCH($Y$7,LenU,0)))^2*(0),INDEX(HeadK,MATCH(AC13,HeadU,0))*(Y13*INDEX(LenF,MATCH($Y$7,LenU,0)))^3)),0),"") | AE13: =IF(OR(E13="",E13="Piping"),"",IF(E13="Exchanger",AQ13*AR13+IF(P13="",0,IF(P13="Conical",PI()/12*(SQRT(4*AQ13/PI()))^2*(0),INDEX(HeadK,MATCH(P13,HeadU,0))*(SQRT(4*AQ13/PI()))^3))-IF(AND(ISNUMBER(S13),ISNUMBER(V13)),S13*PI()/4*AP13^2*V13*INDEX(LenF,MATCH($V$7,LenU,0)),0),IF(ISNUMBER(N13),PI()/4*(N13*INDEX(LenF,MATCH($N$7,LenU,0)))^2*N(O13)*INDEX(LenF,MATCH($O$7,LenU,0))+IF(P13="",0,IF(P13="Conical",PI()/12*(N13*INDEX(LenF,MATCH($N$7,LenU,0)))^2*(N(R13)*INDEX(LenF,MATCH($R$7,LenU,0))),INDEX(HeadK,MATCH(P13,HeadU,0))*(N13*INDEX(LenF,MATCH($N$7,LenU,0)))^3))+IF(Q13="",0,IF(Q13="Conical",PI()/12*(N13*INDEX(LenF,MATCH($N$7,LenU,0)))^2*(N(R13)*INDEX(LenF,MATCH($R$7,LenU,0))),INDEX(HeadK,MATCH(Q13,HeadU,0))*(N13*INDEX(LenF,MATCH($N$7,LenU,0)))^3)),0))) | AF13: =IF(E13<>"Piping","",IF(AND(ISNUMBER(AS13),ISNUMBER(M13)),PI()/4*(AS13/1000)^2*M13*INDEX(LenF,MATCH($M$7,LenU,0)),0)) -> 2.2375032 | AG13: =IF(E13="","",N(AD13)+N(AE13)+N(AF13)) -> 2.2375032 | AH13: =IF(ISNUMBER(I13),I13*INDEX(WtF,MATCH($I$7,WtU,0))/CC_WaterRho,"") | AM13: =IF(AO13="","",AO13*IF(ISNUMBER(AK13),AK13,CC_DefFills)*(1+IF(ISNUMBER(AL13),AL13,CC_DefAllow))) -> 16.082054 | AN13: =IF(G13="Given volume",IF(ISNUMBER(H13),H13*INDEX(VolF,MATCH($H$7,VolU,0)),""),IF(G13="Water weight",AH13,IF(N(AG13)=0,"",AG13))) -> 2.2375032 | AO13: =IF(N(AN13)=0,"",AN13*AT13*IF(ISNUMBER(AJ13),AJ13,CC_DefCirc)) -> 2.5731287 | AP13: =IF(ISNUMBER(T13),T13*INDEX(LenF,MATCH($T$7,LenU,0)),IF(ISNUMBER(W13),W13*INDEX(LenF,MATCH($W$7,LenU,0))/CC_PitchRatio,0)) -> 0 | AQ13: =IF(ISNUMBER(N13),PI()/4*(N13*INDEX(LenF,MATCH($N$7,LenU,0)))^2,IF(AND(ISNUMBER(S13),ISNUMBER(W13),X13<>""),S13*(W13*INDEX(LenF,MATCH($W$7,LenU,0)))^2*INDEX(LayoutF,MATCH(X13,LayoutU,0)),0)) -> 0 | AR13: =IF(ISNUMBER(O13),O13*INDEX(LenF,MATCH($O$7,LenU,0)),IF(ISNUMBER(V13),V13*INDEX(LenF,MATCH($V$7,LenU,0)),0)) -> 0 | AS13: =IF(ISNUMBER(L13),L13*INDEX(LenF,MATCH($L$7,LenU,0))*1000,IF(OR(J13="",K13=""),"",IFERROR(IF(INDEX(PipeWT,MATCH(J13,NPSU,0),MATCH(K13,SchU,0))="","Sch n/a",INDEX(PipeOD,MATCH(J13,NPSU,0))-2*INDEX(PipeWT,MATCH(J13,NPSU,0),MATCH(K13,SchU,0))),""))) -> 154.08 | AT13: =IF(ISNUMBER(AI13),AI13,IFERROR(INDEX(IF(CC_JobType="Decontamination",CC_TypeFillDC,CC_TypeFillCC),MATCH(E13,CC_TypeL,0)),1)) -> 1 | AU13: 1
A14: 5 | AD14: =IF(E14="Exchanger",IF(AND(ISNUMBER(S14),ISNUMBER(U14),ISNUMBER(V14)),S14*PI()/4*(U14*INDEX(LenF,MATCH($U$7,LenU,0)))^2*V14*INDEX(LenF,MATCH($V$7,LenU,0)),0)+IF(ISNUMBER(Y14),PI()/4*(Y14*INDEX(LenF,MATCH($Y$7,LenU,0)))^2*N(Z14)*INDEX(LenF,MATCH($Z$7,LenU,0))+IF(AA14="",0,IF(AA14="Conical",PI()/12*(Y14*INDEX(LenF,MATCH($Y$7,LenU,0)))^2*(0),INDEX(HeadK,MATCH(AA14,HeadU,0))*(Y14*INDEX(LenF,MATCH($Y$7,LenU,0)))^3)),0)+IF(ISNUMBER(Y14),PI()/4*(Y14*INDEX(LenF,MATCH($Y$7,LenU,0)))^2*N(AB14)*INDEX(LenF,MATCH($AB$7,LenU,0))+IF(AC14="",0,IF(AC14="Conical",PI()/12*(Y14*INDEX(LenF,MATCH($Y$7,LenU,0)))^2*(0),INDEX(HeadK,MATCH(AC14,HeadU,0))*(Y14*INDEX(LenF,MATCH($Y$7,LenU,0)))^3)),0),"") | AE14: =IF(OR(E14="",E14="Piping"),"",IF(E14="Exchanger",AQ14*AR14+IF(P14="",0,IF(P14="Conical",PI()/12*(SQRT(4*AQ14/PI()))^2*(0),INDEX(HeadK,MATCH(P14,HeadU,0))*(SQRT(4*AQ14/PI()))^3))-IF(AND(ISNUMBER(S14),ISNUMBER(V14)),S14*PI()/4*AP14^2*V14*INDEX(LenF,MATCH($V$7,LenU,0)),0),IF(ISNUMBER(N14),PI()/4*(N14*INDEX(LenF,MATCH($N$7,LenU,0)))^2*N(O14)*INDEX(LenF,MATCH($O$7,LenU,0))+IF(P14="",0,IF(P14="Conical",PI()/12*(N14*INDEX(LenF,MATCH($N$7,LenU,0)))^2*(N(R14)*INDEX(LenF,MATCH($R$7,LenU,0))),INDEX(HeadK,MATCH(P14,HeadU,0))*(N14*INDEX(LenF,MATCH($N$7,LenU,0)))^3))+IF(Q14="",0,IF(Q14="Conical",PI()/12*(N14*INDEX(LenF,MATCH($N$7,LenU,0)))^2*(N(R14)*INDEX(LenF,MATCH($R$7,LenU,0))),INDEX(HeadK,MATCH(Q14,HeadU,0))*(N14*INDEX(LenF,MATCH($N$7,LenU,0)))^3)),0))) | AF14: =IF(E14<>"Piping","",IF(AND(ISNUMBER(AS14),ISNUMBER(M14)),PI()/4*(AS14/1000)^2*M14*INDEX(LenF,MATCH($M$7,LenU,0)),0)) | AG14: =IF(E14="","",N(AD14)+N(AE14)+N(AF14)) | AH14: =IF(ISNUMBER(I14),I14*INDEX(WtF,MATCH($I$7,WtU,0))/CC_WaterRho,"") | AM14: =IF(AO14="","",AO14*IF(ISNUMBER(AK14),AK14,CC_DefFills)*(1+IF(ISNUMBER(AL14),AL14,CC_DefAllow))) | AN14: =IF(G14="Given volume",IF(ISNUMBER(H14),H14*INDEX(VolF,MATCH($H$7,VolU,0)),""),IF(G14="Water weight",AH14,IF(N(AG14)=0,"",AG14))) | AO14: =IF(N(AN14)=0,"",AN14*AT14*IF(ISNUMBER(AJ14),AJ14,CC_DefCirc)) | AP14: =IF(ISNUMBER(T14),T14*INDEX(LenF,MATCH($T$7,LenU,0)),IF(ISNUMBER(W14),W14*INDEX(LenF,MATCH($W$7,LenU,0))/CC_PitchRatio,0)) -> 0 | AQ14: =IF(ISNUMBER(N14),PI()/4*(N14*INDEX(LenF,MATCH($N$7,LenU,0)))^2,IF(AND(ISNUMBER(S14),ISNUMBER(W14),X14<>""),S14*(W14*INDEX(LenF,MATCH($W$7,LenU,0)))^2*INDEX(LayoutF,MATCH(X14,LayoutU,0)),0)) -> 0 | AR14: =IF(ISNUMBER(O14),O14*INDEX(LenF,MATCH($O$7,LenU,0)),IF(ISNUMBER(V14),V14*INDEX(LenF,MATCH($V$7,LenU,0)),0)) -> 0 | AS14: =IF(ISNUMBER(L14),L14*INDEX(LenF,MATCH($L$7,LenU,0))*1000,IF(OR(J14="",K14=""),"",IFERROR(IF(INDEX(PipeWT,MATCH(J14,NPSU,0),MATCH(K14,SchU,0))="","Sch n/a",INDEX(PipeOD,MATCH(J14,NPSU,0))-2*INDEX(PipeWT,MATCH(J14,NPSU,0),MATCH(K14,SchU,0))),""))) | AT14: =IF(ISNUMBER(AI14),AI14,IFERROR(INDEX(IF(CC_JobType="Decontamination",CC_TypeFillDC,CC_TypeFillCC),MATCH(E14,CC_TypeL,0)),1)) -> 1 | AU14: 1
A15: 6 | AD15: =IF(E15="Exchanger",IF(AND(ISNUMBER(S15),ISNUMBER(U15),ISNUMBER(V15)),S15*PI()/4*(U15*INDEX(LenF,MATCH($U$7,LenU,0)))^2*V15*INDEX(LenF,MATCH($V$7,LenU,0)),0)+IF(ISNUMBER(Y15),PI()/4*(Y15*INDEX(LenF,MATCH($Y$7,LenU,0)))^2*N(Z15)*INDEX(LenF,MATCH($Z$7,LenU,0))+IF(AA15="",0,IF(AA15="Conical",PI()/12*(Y15*INDEX(LenF,MATCH($Y$7,LenU,0)))^2*(0),INDEX(HeadK,MATCH(AA15,HeadU,0))*(Y15*INDEX(LenF,MATCH($Y$7,LenU,0)))^3)),0)+IF(ISNUMBER(Y15),PI()/4*(Y15*INDEX(LenF,MATCH($Y$7,LenU,0)))^2*N(AB15)*INDEX(LenF,MATCH($AB$7,LenU,0))+IF(AC15="",0,IF(AC15="Conical",PI()/12*(Y15*INDEX(LenF,MATCH($Y$7,LenU,0)))^2*(0),INDEX(HeadK,MATCH(AC15,HeadU,0))*(Y15*INDEX(LenF,MATCH($Y$7,LenU,0)))^3)),0),"") | AE15: =IF(OR(E15="",E15="Piping"),"",IF(E15="Exchanger",AQ15*AR15+IF(P15="",0,IF(P15="Conical",PI()/12*(SQRT(4*AQ15/PI()))^2*(0),INDEX(HeadK,MATCH(P15,HeadU,0))*(SQRT(4*AQ15/PI()))^3))-IF(AND(ISNUMBER(S15),ISNUMBER(V15)),S15*PI()/4*AP15^2*V15*INDEX(LenF,MATCH($V$7,LenU,0)),0),IF(ISNUMBER(N15),PI()/4*(N15*INDEX(LenF,MATCH($N$7,LenU,0)))^2*N(O15)*INDEX(LenF,MATCH($O$7,LenU,0))+IF(P15="",0,IF(P15="Conical",PI()/12*(N15*INDEX(LenF,MATCH($N$7,LenU,0)))^2*(N(R15)*INDEX(LenF,MATCH($R$7,LenU,0))),INDEX(HeadK,MATCH(P15,HeadU,0))*(N15*INDEX(LenF,MATCH($N$7,LenU,0)))^3))+IF(Q15="",0,IF(Q15="Conical",PI()/12*(N15*INDEX(LenF,MATCH($N$7,LenU,0)))^2*(N(R15)*INDEX(LenF,MATCH($R$7,LenU,0))),INDEX(HeadK,MATCH(Q15,HeadU,0))*(N15*INDEX(LenF,MATCH($N$7,LenU,0)))^3)),0))) | AF15: =IF(E15<>"Piping","",IF(AND(ISNUMBER(AS15),ISNUMBER(M15)),PI()/4*(AS15/1000)^2*M15*INDEX(LenF,MATCH($M$7,LenU,0)),0)) | AG15: =IF(E15="","",N(AD15)+N(AE15)+N(AF15)) | AH15: =IF(ISNUMBER(I15),I15*INDEX(WtF,MATCH($I$7,WtU,0))/CC_WaterRho,"") | AM15: =IF(AO15="","",AO15*IF(ISNUMBER(AK15),AK15,CC_DefFills)*(1+IF(ISNUMBER(AL15),AL15,CC_DefAllow))) | AN15: =IF(G15="Given volume",IF(ISNUMBER(H15),H15*INDEX(VolF,MATCH($H$7,VolU,0)),""),IF(G15="Water weight",AH15,IF(N(AG15)=0,"",AG15))) | AO15: =IF(N(AN15)=0,"",AN15*AT15*IF(ISNUMBER(AJ15),AJ15,CC_DefCirc)) | AP15: =IF(ISNUMBER(T15),T15*INDEX(LenF,MATCH($T$7,LenU,0)),IF(ISNUMBER(W15),W15*INDEX(LenF,MATCH($W$7,LenU,0))/CC_PitchRatio,0)) -> 0 | AQ15: =IF(ISNUMBER(N15),PI()/4*(N15*INDEX(LenF,MATCH($N$7,LenU,0)))^2,IF(AND(ISNUMBER(S15),ISNUMBER(W15),X15<>""),S15*(W15*INDEX(LenF,MATCH($W$7,LenU,0)))^2*INDEX(LayoutF,MATCH(X15,LayoutU,0)),0)) -> 0 | AR15: =IF(ISNUMBER(O15),O15*INDEX(LenF,MATCH($O$7,LenU,0)),IF(ISNUMBER(V15),V15*INDEX(LenF,MATCH($V$7,LenU,0)),0)) -> 0 | AS15: =IF(ISNUMBER(L15),L15*INDEX(LenF,MATCH($L$7,LenU,0))*1000,IF(OR(J15="",K15=""),"",IFERROR(IF(INDEX(PipeWT,MATCH(J15,NPSU,0),MATCH(K15,SchU,0))="","Sch n/a",INDEX(PipeOD,MATCH(J15,NPSU,0))-2*INDEX(PipeWT,MATCH(J15,NPSU,0),MATCH(K15,SchU,0))),""))) | AT15: =IF(ISNUMBER(AI15),AI15,IFERROR(INDEX(IF(CC_JobType="Decontamination",CC_TypeFillDC,CC_TypeFillCC),MATCH(E15,CC_TypeL,0)),1)) -> 1 | AU15: 1
A16: 7 | AD16: =IF(E16="Exchanger",IF(AND(ISNUMBER(S16),ISNUMBER(U16),ISNUMBER(V16)),S16*PI()/4*(U16*INDEX(LenF,MATCH($U$7,LenU,0)))^2*V16*INDEX(LenF,MATCH($V$7,LenU,0)),0)+IF(ISNUMBER(Y16),PI()/4*(Y16*INDEX(LenF,MATCH($Y$7,LenU,0)))^2*N(Z16)*INDEX(LenF,MATCH($Z$7,LenU,0))+IF(AA16="",0,IF(AA16="Conical",PI()/12*(Y16*INDEX(LenF,MATCH($Y$7,LenU,0)))^2*(0),INDEX(HeadK,MATCH(AA16,HeadU,0))*(Y16*INDEX(LenF,MATCH($Y$7,LenU,0)))^3)),0)+IF(ISNUMBER(Y16),PI()/4*(Y16*INDEX(LenF,MATCH($Y$7,LenU,0)))^2*N(AB16)*INDEX(LenF,MATCH($AB$7,LenU,0))+IF(AC16="",0,IF(AC16="Conical",PI()/12*(Y16*INDEX(LenF,MATCH($Y$7,LenU,0)))^2*(0),INDEX(HeadK,MATCH(AC16,HeadU,0))*(Y16*INDEX(LenF,MATCH($Y$7,LenU,0)))^3)),0),"") | AE16: =IF(OR(E16="",E16="Piping"),"",IF(E16="Exchanger",AQ16*AR16+IF(P16="",0,IF(P16="Conical",PI()/12*(SQRT(4*AQ16/PI()))^2*(0),INDEX(HeadK,MATCH(P16,HeadU,0))*(SQRT(4*AQ16/PI()))^3))-IF(AND(ISNUMBER(S16),ISNUMBER(V16)),S16*PI()/4*AP16^2*V16*INDEX(LenF,MATCH($V$7,LenU,0)),0),IF(ISNUMBER(N16),PI()/4*(N16*INDEX(LenF,MATCH($N$7,LenU,0)))^2*N(O16)*INDEX(LenF,MATCH($O$7,LenU,0))+IF(P16="",0,IF(P16="Conical",PI()/12*(N16*INDEX(LenF,MATCH($N$7,LenU,0)))^2*(N(R16)*INDEX(LenF,MATCH($R$7,LenU,0))),INDEX(HeadK,MATCH(P16,HeadU,0))*(N16*INDEX(LenF,MATCH($N$7,LenU,0)))^3))+IF(Q16="",0,IF(Q16="Conical",PI()/12*(N16*INDEX(LenF,MATCH($N$7,LenU,0)))^2*(N(R16)*INDEX(LenF,MATCH($R$7,LenU,0))),INDEX(HeadK,MATCH(Q16,HeadU,0))*(N16*INDEX(LenF,MATCH($N$7,LenU,0)))^3)),0))) | AF16: =IF(E16<>"Piping","",IF(AND(ISNUMBER(AS16),ISNUMBER(M16)),PI()/4*(AS16/1000)^2*M16*INDEX(LenF,MATCH($M$7,LenU,0)),0)) | AG16: =IF(E16="","",N(AD16)+N(AE16)+N(AF16)) | AH16: =IF(ISNUMBER(I16),I16*INDEX(WtF,MATCH($I$7,WtU,0))/CC_WaterRho,"") | AM16: =IF(AO16="","",AO16*IF(ISNUMBER(AK16),AK16,CC_DefFills)*(1+IF(ISNUMBER(AL16),AL16,CC_DefAllow))) | AN16: =IF(G16="Given volume",IF(ISNUMBER(H16),H16*INDEX(VolF,MATCH($H$7,VolU,0)),""),IF(G16="Water weight",AH16,IF(N(AG16)=0,"",AG16))) | AO16: =IF(N(AN16)=0,"",AN16*AT16*IF(ISNUMBER(AJ16),AJ16,CC_DefCirc)) | AP16: =IF(ISNUMBER(T16),T16*INDEX(LenF,MATCH($T$7,LenU,0)),IF(ISNUMBER(W16),W16*INDEX(LenF,MATCH($W$7,LenU,0))/CC_PitchRatio,0)) -> 0 | AQ16: =IF(ISNUMBER(N16),PI()/4*(N16*INDEX(LenF,MATCH($N$7,LenU,0)))^2,IF(AND(ISNUMBER(S16),ISNUMBER(W16),X16<>""),S16*(W16*INDEX(LenF,MATCH($W$7,LenU,0)))^2*INDEX(LayoutF,MATCH(X16,LayoutU,0)),0)) -> 0 | AR16: =IF(ISNUMBER(O16),O16*INDEX(LenF,MATCH($O$7,LenU,0)),IF(ISNUMBER(V16),V16*INDEX(LenF,MATCH($V$7,LenU,0)),0)) -> 0 | AS16: =IF(ISNUMBER(L16),L16*INDEX(LenF,MATCH($L$7,LenU,0))*1000,IF(OR(J16="",K16=""),"",IFERROR(IF(INDEX(PipeWT,MATCH(J16,NPSU,0),MATCH(K16,SchU,0))="","Sch n/a",INDEX(PipeOD,MATCH(J16,NPSU,0))-2*INDEX(PipeWT,MATCH(J16,NPSU,0),MATCH(K16,SchU,0))),""))) | AT16: =IF(ISNUMBER(AI16),AI16,IFERROR(INDEX(IF(CC_JobType="Decontamination",CC_TypeFillDC,CC_TypeFillCC),MATCH(E16,CC_TypeL,0)),1)) -> 1 | AU16: 1
A17: 8 | AD17: =IF(E17="Exchanger",IF(AND(ISNUMBER(S17),ISNUMBER(U17),ISNUMBER(V17)),S17*PI()/4*(U17*INDEX(LenF,MATCH($U$7,LenU,0)))^2*V17*INDEX(LenF,MATCH($V$7,LenU,0)),0)+IF(ISNUMBER(Y17),PI()/4*(Y17*INDEX(LenF,MATCH($Y$7,LenU,0)))^2*N(Z17)*INDEX(LenF,MATCH($Z$7,LenU,0))+IF(AA17="",0,IF(AA17="Conical",PI()/12*(Y17*INDEX(LenF,MATCH($Y$7,LenU,0)))^2*(0),INDEX(HeadK,MATCH(AA17,HeadU,0))*(Y17*INDEX(LenF,MATCH($Y$7,LenU,0)))^3)),0)+IF(ISNUMBER(Y17),PI()/4*(Y17*INDEX(LenF,MATCH($Y$7,LenU,0)))^2*N(AB17)*INDEX(LenF,MATCH($AB$7,LenU,0))+IF(AC17="",0,IF(AC17="Conical",PI()/12*(Y17*INDEX(LenF,MATCH($Y$7,LenU,0)))^2*(0),INDEX(HeadK,MATCH(AC17,HeadU,0))*(Y17*INDEX(LenF,MATCH($Y$7,LenU,0)))^3)),0),"") | AE17: =IF(OR(E17="",E17="Piping"),"",IF(E17="Exchanger",AQ17*AR17+IF(P17="",0,IF(P17="Conical",PI()/12*(SQRT(4*AQ17/PI()))^2*(0),INDEX(HeadK,MATCH(P17,HeadU,0))*(SQRT(4*AQ17/PI()))^3))-IF(AND(ISNUMBER(S17),ISNUMBER(V17)),S17*PI()/4*AP17^2*V17*INDEX(LenF,MATCH($V$7,LenU,0)),0),IF(ISNUMBER(N17),PI()/4*(N17*INDEX(LenF,MATCH($N$7,LenU,0)))^2*N(O17)*INDEX(LenF,MATCH($O$7,LenU,0))+IF(P17="",0,IF(P17="Conical",PI()/12*(N17*INDEX(LenF,MATCH($N$7,LenU,0)))^2*(N(R17)*INDEX(LenF,MATCH($R$7,LenU,0))),INDEX(HeadK,MATCH(P17,HeadU,0))*(N17*INDEX(LenF,MATCH($N$7,LenU,0)))^3))+IF(Q17="",0,IF(Q17="Conical",PI()/12*(N17*INDEX(LenF,MATCH($N$7,LenU,0)))^2*(N(R17)*INDEX(LenF,MATCH($R$7,LenU,0))),INDEX(HeadK,MATCH(Q17,HeadU,0))*(N17*INDEX(LenF,MATCH($N$7,LenU,0)))^3)),0))) | AF17: =IF(E17<>"Piping","",IF(AND(ISNUMBER(AS17),ISNUMBER(M17)),PI()/4*(AS17/1000)^2*M17*INDEX(LenF,MATCH($M$7,LenU,0)),0)) | AG17: =IF(E17="","",N(AD17)+N(AE17)+N(AF17)) | AH17: =IF(ISNUMBER(I17),I17*INDEX(WtF,MATCH($I$7,WtU,0))/CC_WaterRho,"") | AM17: =IF(AO17="","",AO17*IF(ISNUMBER(AK17),AK17,CC_DefFills)*(1+IF(ISNUMBER(AL17),AL17,CC_DefAllow))) | AN17: =IF(G17="Given volume",IF(ISNUMBER(H17),H17*INDEX(VolF,MATCH($H$7,VolU,0)),""),IF(G17="Water weight",AH17,IF(N(AG17)=0,"",AG17))) | AO17: =IF(N(AN17)=0,"",AN17*AT17*IF(ISNUMBER(AJ17),AJ17,CC_DefCirc)) | AP17: =IF(ISNUMBER(T17),T17*INDEX(LenF,MATCH($T$7,LenU,0)),IF(ISNUMBER(W17),W17*INDEX(LenF,MATCH($W$7,LenU,0))/CC_PitchRatio,0)) -> 0 | AQ17: =IF(ISNUMBER(N17),PI()/4*(N17*INDEX(LenF,MATCH($N$7,LenU,0)))^2,IF(AND(ISNUMBER(S17),ISNUMBER(W17),X17<>""),S17*(W17*INDEX(LenF,MATCH($W$7,LenU,0)))^2*INDEX(LayoutF,MATCH(X17,LayoutU,0)),0)) -> 0 | AR17: =IF(ISNUMBER(O17),O17*INDEX(LenF,MATCH($O$7,LenU,0)),IF(ISNUMBER(V17),V17*INDEX(LenF,MATCH($V$7,LenU,0)),0)) -> 0 | AS17: =IF(ISNUMBER(L17),L17*INDEX(LenF,MATCH($L$7,LenU,0))*1000,IF(OR(J17="",K17=""),"",IFERROR(IF(INDEX(PipeWT,MATCH(J17,NPSU,0),MATCH(K17,SchU,0))="","Sch n/a",INDEX(PipeOD,MATCH(J17,NPSU,0))-2*INDEX(PipeWT,MATCH(J17,NPSU,0),MATCH(K17,SchU,0))),""))) | AT17: =IF(ISNUMBER(AI17),AI17,IFERROR(INDEX(IF(CC_JobType="Decontamination",CC_TypeFillDC,CC_TypeFillCC),MATCH(E17,CC_TypeL,0)),1)) -> 1 | AU17: 1
A18: 9 | AD18: =IF(E18="Exchanger",IF(AND(ISNUMBER(S18),ISNUMBER(U18),ISNUMBER(V18)),S18*PI()/4*(U18*INDEX(LenF,MATCH($U$7,LenU,0)))^2*V18*INDEX(LenF,MATCH($V$7,LenU,0)),0)+IF(ISNUMBER(Y18),PI()/4*(Y18*INDEX(LenF,MATCH($Y$7,LenU,0)))^2*N(Z18)*INDEX(LenF,MATCH($Z$7,LenU,0))+IF(AA18="",0,IF(AA18="Conical",PI()/12*(Y18*INDEX(LenF,MATCH($Y$7,LenU,0)))^2*(0),INDEX(HeadK,MATCH(AA18,HeadU,0))*(Y18*INDEX(LenF,MATCH($Y$7,LenU,0)))^3)),0)+IF(ISNUMBER(Y18),PI()/4*(Y18*INDEX(LenF,MATCH($Y$7,LenU,0)))^2*N(AB18)*INDEX(LenF,MATCH($AB$7,LenU,0))+IF(AC18="",0,IF(AC18="Conical",PI()/12*(Y18*INDEX(LenF,MATCH($Y$7,LenU,0)))^2*(0),INDEX(HeadK,MATCH(AC18,HeadU,0))*(Y18*INDEX(LenF,MATCH($Y$7,LenU,0)))^3)),0),"") | AE18: =IF(OR(E18="",E18="Piping"),"",IF(E18="Exchanger",AQ18*AR18+IF(P18="",0,IF(P18="Conical",PI()/12*(SQRT(4*AQ18/PI()))^2*(0),INDEX(HeadK,MATCH(P18,HeadU,0))*(SQRT(4*AQ18/PI()))^3))-IF(AND(ISNUMBER(S18),ISNUMBER(V18)),S18*PI()/4*AP18^2*V18*INDEX(LenF,MATCH($V$7,LenU,0)),0),IF(ISNUMBER(N18),PI()/4*(N18*INDEX(LenF,MATCH($N$7,LenU,0)))^2*N(O18)*INDEX(LenF,MATCH($O$7,LenU,0))+IF(P18="",0,IF(P18="Conical",PI()/12*(N18*INDEX(LenF,MATCH($N$7,LenU,0)))^2*(N(R18)*INDEX(LenF,MATCH($R$7,LenU,0))),INDEX(HeadK,MATCH(P18,HeadU,0))*(N18*INDEX(LenF,MATCH($N$7,LenU,0)))^3))+IF(Q18="",0,IF(Q18="Conical",PI()/12*(N18*INDEX(LenF,MATCH($N$7,LenU,0)))^2*(N(R18)*INDEX(LenF,MATCH($R$7,LenU,0))),INDEX(HeadK,MATCH(Q18,HeadU,0))*(N18*INDEX(LenF,MATCH($N$7,LenU,0)))^3)),0))) | AF18: =IF(E18<>"Piping","",IF(AND(ISNUMBER(AS18),ISNUMBER(M18)),PI()/4*(AS18/1000)^2*M18*INDEX(LenF,MATCH($M$7,LenU,0)),0)) | AG18: =IF(E18="","",N(AD18)+N(AE18)+N(AF18)) | AH18: =IF(ISNUMBER(I18),I18*INDEX(WtF,MATCH($I$7,WtU,0))/CC_WaterRho,"") | AM18: =IF(AO18="","",AO18*IF(ISNUMBER(AK18),AK18,CC_DefFills)*(1+IF(ISNUMBER(AL18),AL18,CC_DefAllow))) | AN18: =IF(G18="Given volume",IF(ISNUMBER(H18),H18*INDEX(VolF,MATCH($H$7,VolU,0)),""),IF(G18="Water weight",AH18,IF(N(AG18)=0,"",AG18))) | AO18: =IF(N(AN18)=0,"",AN18*AT18*IF(ISNUMBER(AJ18),AJ18,CC_DefCirc)) | AP18: =IF(ISNUMBER(T18),T18*INDEX(LenF,MATCH($T$7,LenU,0)),IF(ISNUMBER(W18),W18*INDEX(LenF,MATCH($W$7,LenU,0))/CC_PitchRatio,0)) -> 0 | AQ18: =IF(ISNUMBER(N18),PI()/4*(N18*INDEX(LenF,MATCH($N$7,LenU,0)))^2,IF(AND(ISNUMBER(S18),ISNUMBER(W18),X18<>""),S18*(W18*INDEX(LenF,MATCH($W$7,LenU,0)))^2*INDEX(LayoutF,MATCH(X18,LayoutU,0)),0)) -> 0 | AR18: =IF(ISNUMBER(O18),O18*INDEX(LenF,MATCH($O$7,LenU,0)),IF(ISNUMBER(V18),V18*INDEX(LenF,MATCH($V$7,LenU,0)),0)) -> 0 | AS18: =IF(ISNUMBER(L18),L18*INDEX(LenF,MATCH($L$7,LenU,0))*1000,IF(OR(J18="",K18=""),"",IFERROR(IF(INDEX(PipeWT,MATCH(J18,NPSU,0),MATCH(K18,SchU,0))="","Sch n/a",INDEX(PipeOD,MATCH(J18,NPSU,0))-2*INDEX(PipeWT,MATCH(J18,NPSU,0),MATCH(K18,SchU,0))),""))) | AT18: =IF(ISNUMBER(AI18),AI18,IFERROR(INDEX(IF(CC_JobType="Decontamination",CC_TypeFillDC,CC_TypeFillCC),MATCH(E18,CC_TypeL,0)),1)) -> 1 | AU18: 1
A19: 10 | AD19: =IF(E19="Exchanger",IF(AND(ISNUMBER(S19),ISNUMBER(U19),ISNUMBER(V19)),S19*PI()/4*(U19*INDEX(LenF,MATCH($U$7,LenU,0)))^2*V19*INDEX(LenF,MATCH($V$7,LenU,0)),0)+IF(ISNUMBER(Y19),PI()/4*(Y19*INDEX(LenF,MATCH($Y$7,LenU,0)))^2*N(Z19)*INDEX(LenF,MATCH($Z$7,LenU,0))+IF(AA19="",0,IF(AA19="Conical",PI()/12*(Y19*INDEX(LenF,MATCH($Y$7,LenU,0)))^2*(0),INDEX(HeadK,MATCH(AA19,HeadU,0))*(Y19*INDEX(LenF,MATCH($Y$7,LenU,0)))^3)),0)+IF(ISNUMBER(Y19),PI()/4*(Y19*INDEX(LenF,MATCH($Y$7,LenU,0)))^2*N(AB19)*INDEX(LenF,MATCH($AB$7,LenU,0))+IF(AC19="",0,IF(AC19="Conical",PI()/12*(Y19*INDEX(LenF,MATCH($Y$7,LenU,0)))^2*(0),INDEX(HeadK,MATCH(AC19,HeadU,0))*(Y19*INDEX(LenF,MATCH($Y$7,LenU,0)))^3)),0),"") | AE19: =IF(OR(E19="",E19="Piping"),"",IF(E19="Exchanger",AQ19*AR19+IF(P19="",0,IF(P19="Conical",PI()/12*(SQRT(4*AQ19/PI()))^2*(0),INDEX(HeadK,MATCH(P19,HeadU,0))*(SQRT(4*AQ19/PI()))^3))-IF(AND(ISNUMBER(S19),ISNUMBER(V19)),S19*PI()/4*AP19^2*V19*INDEX(LenF,MATCH($V$7,LenU,0)),0),IF(ISNUMBER(N19),PI()/4*(N19*INDEX(LenF,MATCH($N$7,LenU,0)))^2*N(O19)*INDEX(LenF,MATCH($O$7,LenU,0))+IF(P19="",0,IF(P19="Conical",PI()/12*(N19*INDEX(LenF,MATCH($N$7,LenU,0)))^2*(N(R19)*INDEX(LenF,MATCH($R$7,LenU,0))),INDEX(HeadK,MATCH(P19,HeadU,0))*(N19*INDEX(LenF,MATCH($N$7,LenU,0)))^3))+IF(Q19="",0,IF(Q19="Conical",PI()/12*(N19*INDEX(LenF,MATCH($N$7,LenU,0)))^2*(N(R19)*INDEX(LenF,MATCH($R$7,LenU,0))),INDEX(HeadK,MATCH(Q19,HeadU,0))*(N19*INDEX(LenF,MATCH($N$7,LenU,0)))^3)),0))) | AF19: =IF(E19<>"Piping","",IF(AND(ISNUMBER(AS19),ISNUMBER(M19)),PI()/4*(AS19/1000)^2*M19*INDEX(LenF,MATCH($M$7,LenU,0)),0)) | AG19: =IF(E19="","",N(AD19)+N(AE19)+N(AF19)) | AH19: =IF(ISNUMBER(I19),I19*INDEX(WtF,MATCH($I$7,WtU,0))/CC_WaterRho,"") | AM19: =IF(AO19="","",AO19*IF(ISNUMBER(AK19),AK19,CC_DefFills)*(1+IF(ISNUMBER(AL19),AL19,CC_DefAllow))) | AN19: =IF(G19="Given volume",IF(ISNUMBER(H19),H19*INDEX(VolF,MATCH($H$7,VolU,0)),""),IF(G19="Water weight",AH19,IF(N(AG19)=0,"",AG19))) | AO19: =IF(N(AN19)=0,"",AN19*AT19*IF(ISNUMBER(AJ19),AJ19,CC_DefCirc)) | AP19: =IF(ISNUMBER(T19),T19*INDEX(LenF,MATCH($T$7,LenU,0)),IF(ISNUMBER(W19),W19*INDEX(LenF,MATCH($W$7,LenU,0))/CC_PitchRatio,0)) -> 0 | AQ19: =IF(ISNUMBER(N19),PI()/4*(N19*INDEX(LenF,MATCH($N$7,LenU,0)))^2,IF(AND(ISNUMBER(S19),ISNUMBER(W19),X19<>""),S19*(W19*INDEX(LenF,MATCH($W$7,LenU,0)))^2*INDEX(LayoutF,MATCH(X19,LayoutU,0)),0)) -> 0 | AR19: =IF(ISNUMBER(O19),O19*INDEX(LenF,MATCH($O$7,LenU,0)),IF(ISNUMBER(V19),V19*INDEX(LenF,MATCH($V$7,LenU,0)),0)) -> 0 | AS19: =IF(ISNUMBER(L19),L19*INDEX(LenF,MATCH($L$7,LenU,0))*1000,IF(OR(J19="",K19=""),"",IFERROR(IF(INDEX(PipeWT,MATCH(J19,NPSU,0),MATCH(K19,SchU,0))="","Sch n/a",INDEX(PipeOD,MATCH(J19,NPSU,0))-2*INDEX(PipeWT,MATCH(J19,NPSU,0),MATCH(K19,SchU,0))),""))) | AT19: =IF(ISNUMBER(AI19),AI19,IFERROR(INDEX(IF(CC_JobType="Decontamination",CC_TypeFillDC,CC_TypeFillCC),MATCH(E19,CC_TypeL,0)),1)) -> 1 | AU19: 1
A20: 11 | AD20: =IF(E20="Exchanger",IF(AND(ISNUMBER(S20),ISNUMBER(U20),ISNUMBER(V20)),S20*PI()/4*(U20*INDEX(LenF,MATCH($U$7,LenU,0)))^2*V20*INDEX(LenF,MATCH($V$7,LenU,0)),0)+IF(ISNUMBER(Y20),PI()/4*(Y20*INDEX(LenF,MATCH($Y$7,LenU,0)))^2*N(Z20)*INDEX(LenF,MATCH($Z$7,LenU,0))+IF(AA20="",0,IF(AA20="Conical",PI()/12*(Y20*INDEX(LenF,MATCH($Y$7,LenU,0)))^2*(0),INDEX(HeadK,MATCH(AA20,HeadU,0))*(Y20*INDEX(LenF,MATCH($Y$7,LenU,0)))^3)),0)+IF(ISNUMBER(Y20),PI()/4*(Y20*INDEX(LenF,MATCH($Y$7,LenU,0)))^2*N(AB20)*INDEX(LenF,MATCH($AB$7,LenU,0))+IF(AC20="",0,IF(AC20="Conical",PI()/12*(Y20*INDEX(LenF,MATCH($Y$7,LenU,0)))^2*(0),INDEX(HeadK,MATCH(AC20,HeadU,0))*(Y20*INDEX(LenF,MATCH($Y$7,LenU,0)))^3)),0),"") | AE20: =IF(OR(E20="",E20="Piping"),"",IF(E20="Exchanger",AQ20*AR20+IF(P20="",0,IF(P20="Conical",PI()/12*(SQRT(4*AQ20/PI()))^2*(0),INDEX(HeadK,MATCH(P20,HeadU,0))*(SQRT(4*AQ20/PI()))^3))-IF(AND(ISNUMBER(S20),ISNUMBER(V20)),S20*PI()/4*AP20^2*V20*INDEX(LenF,MATCH($V$7,LenU,0)),0),IF(ISNUMBER(N20),PI()/4*(N20*INDEX(LenF,MATCH($N$7,LenU,0)))^2*N(O20)*INDEX(LenF,MATCH($O$7,LenU,0))+IF(P20="",0,IF(P20="Conical",PI()/12*(N20*INDEX(LenF,MATCH($N$7,LenU,0)))^2*(N(R20)*INDEX(LenF,MATCH($R$7,LenU,0))),INDEX(HeadK,MATCH(P20,HeadU,0))*(N20*INDEX(LenF,MATCH($N$7,LenU,0)))^3))+IF(Q20="",0,IF(Q20="Conical",PI()/12*(N20*INDEX(LenF,MATCH($N$7,LenU,0)))^2*(N(R20)*INDEX(LenF,MATCH($R$7,LenU,0))),INDEX(HeadK,MATCH(Q20,HeadU,0))*(N20*INDEX(LenF,MATCH($N$7,LenU,0)))^3)),0))) | AF20: =IF(E20<>"Piping","",IF(AND(ISNUMBER(AS20),ISNUMBER(M20)),PI()/4*(AS20/1000)^2*M20*INDEX(LenF,MATCH($M$7,LenU,0)),0)) | AG20: =IF(E20="","",N(AD20)+N(AE20)+N(AF20)) | AH20: =IF(ISNUMBER(I20),I20*INDEX(WtF,MATCH($I$7,WtU,0))/CC_WaterRho,"") | AM20: =IF(AO20="","",AO20*IF(ISNUMBER(AK20),AK20,CC_DefFills)*(1+IF(ISNUMBER(AL20),AL20,CC_DefAllow))) | AN20: =IF(G20="Given volume",IF(ISNUMBER(H20),H20*INDEX(VolF,MATCH($H$7,VolU,0)),""),IF(G20="Water weight",AH20,IF(N(AG20)=0,"",AG20))) | AO20: =IF(N(AN20)=0,"",AN20*AT20*IF(ISNUMBER(AJ20),AJ20,CC_DefCirc)) | AP20: =IF(ISNUMBER(T20),T20*INDEX(LenF,MATCH($T$7,LenU,0)),IF(ISNUMBER(W20),W20*INDEX(LenF,MATCH($W$7,LenU,0))/CC_PitchRatio,0)) -> 0 | AQ20: =IF(ISNUMBER(N20),PI()/4*(N20*INDEX(LenF,MATCH($N$7,LenU,0)))^2,IF(AND(ISNUMBER(S20),ISNUMBER(W20),X20<>""),S20*(W20*INDEX(LenF,MATCH($W$7,LenU,0)))^2*INDEX(LayoutF,MATCH(X20,LayoutU,0)),0)) -> 0 | AR20: =IF(ISNUMBER(O20),O20*INDEX(LenF,MATCH($O$7,LenU,0)),IF(ISNUMBER(V20),V20*INDEX(LenF,MATCH($V$7,LenU,0)),0)) -> 0 | AS20: =IF(ISNUMBER(L20),L20*INDEX(LenF,MATCH($L$7,LenU,0))*1000,IF(OR(J20="",K20=""),"",IFERROR(IF(INDEX(PipeWT,MATCH(J20,NPSU,0),MATCH(K20,SchU,0))="","Sch n/a",INDEX(PipeOD,MATCH(J20,NPSU,0))-2*INDEX(PipeWT,MATCH(J20,NPSU,0),MATCH(K20,SchU,0))),""))) | AT20: =IF(ISNUMBER(AI20),AI20,IFERROR(INDEX(IF(CC_JobType="Decontamination",CC_TypeFillDC,CC_TypeFillCC),MATCH(E20,CC_TypeL,0)),1)) -> 1 | AU20: 1
A21: 12 | AD21: =IF(E21="Exchanger",IF(AND(ISNUMBER(S21),ISNUMBER(U21),ISNUMBER(V21)),S21*PI()/4*(U21*INDEX(LenF,MATCH($U$7,LenU,0)))^2*V21*INDEX(LenF,MATCH($V$7,LenU,0)),0)+IF(ISNUMBER(Y21),PI()/4*(Y21*INDEX(LenF,MATCH($Y$7,LenU,0)))^2*N(Z21)*INDEX(LenF,MATCH($Z$7,LenU,0))+IF(AA21="",0,IF(AA21="Conical",PI()/12*(Y21*INDEX(LenF,MATCH($Y$7,LenU,0)))^2*(0),INDEX(HeadK,MATCH(AA21,HeadU,0))*(Y21*INDEX(LenF,MATCH($Y$7,LenU,0)))^3)),0)+IF(ISNUMBER(Y21),PI()/4*(Y21*INDEX(LenF,MATCH($Y$7,LenU,0)))^2*N(AB21)*INDEX(LenF,MATCH($AB$7,LenU,0))+IF(AC21="",0,IF(AC21="Conical",PI()/12*(Y21*INDEX(LenF,MATCH($Y$7,LenU,0)))^2*(0),INDEX(HeadK,MATCH(AC21,HeadU,0))*(Y21*INDEX(LenF,MATCH($Y$7,LenU,0)))^3)),0),"") | AE21: =IF(OR(E21="",E21="Piping"),"",IF(E21="Exchanger",AQ21*AR21+IF(P21="",0,IF(P21="Conical",PI()/12*(SQRT(4*AQ21/PI()))^2*(0),INDEX(HeadK,MATCH(P21,HeadU,0))*(SQRT(4*AQ21/PI()))^3))-IF(AND(ISNUMBER(S21),ISNUMBER(V21)),S21*PI()/4*AP21^2*V21*INDEX(LenF,MATCH($V$7,LenU,0)),0),IF(ISNUMBER(N21),PI()/4*(N21*INDEX(LenF,MATCH($N$7,LenU,0)))^2*N(O21)*INDEX(LenF,MATCH($O$7,LenU,0))+IF(P21="",0,IF(P21="Conical",PI()/12*(N21*INDEX(LenF,MATCH($N$7,LenU,0)))^2*(N(R21)*INDEX(LenF,MATCH($R$7,LenU,0))),INDEX(HeadK,MATCH(P21,HeadU,0))*(N21*INDEX(LenF,MATCH($N$7,LenU,0)))^3))+IF(Q21="",0,IF(Q21="Conical",PI()/12*(N21*INDEX(LenF,MATCH($N$7,LenU,0)))^2*(N(R21)*INDEX(LenF,MATCH($R$7,LenU,0))),INDEX(HeadK,MATCH(Q21,HeadU,0))*(N21*INDEX(LenF,MATCH($N$7,LenU,0)))^3)),0))) | AF21: =IF(E21<>"Piping","",IF(AND(ISNUMBER(AS21),ISNUMBER(M21)),PI()/4*(AS21/1000)^2*M21*INDEX(LenF,MATCH($M$7,LenU,0)),0)) | AG21: =IF(E21="","",N(AD21)+N(AE21)+N(AF21)) | AH21: =IF(ISNUMBER(I21),I21*INDEX(WtF,MATCH($I$7,WtU,0))/CC_WaterRho,"") | AM21: =IF(AO21="","",AO21*IF(ISNUMBER(AK21),AK21,CC_DefFills)*(1+IF(ISNUMBER(AL21),AL21,CC_DefAllow))) | AN21: =IF(G21="Given volume",IF(ISNUMBER(H21),H21*INDEX(VolF,MATCH($H$7,VolU,0)),""),IF(G21="Water weight",AH21,IF(N(AG21)=0,"",AG21))) | AO21: =IF(N(AN21)=0,"",AN21*AT21*IF(ISNUMBER(AJ21),AJ21,CC_DefCirc)) | AP21: =IF(ISNUMBER(T21),T21*INDEX(LenF,MATCH($T$7,LenU,0)),IF(ISNUMBER(W21),W21*INDEX(LenF,MATCH($W$7,LenU,0))/CC_PitchRatio,0)) -> 0 | AQ21: =IF(ISNUMBER(N21),PI()/4*(N21*INDEX(LenF,MATCH($N$7,LenU,0)))^2,IF(AND(ISNUMBER(S21),ISNUMBER(W21),X21<>""),S21*(W21*INDEX(LenF,MATCH($W$7,LenU,0)))^2*INDEX(LayoutF,MATCH(X21,LayoutU,0)),0)) -> 0 | AR21: =IF(ISNUMBER(O21),O21*INDEX(LenF,MATCH($O$7,LenU,0)),IF(ISNUMBER(V21),V21*INDEX(LenF,MATCH($V$7,LenU,0)),0)) -> 0 | AS21: =IF(ISNUMBER(L21),L21*INDEX(LenF,MATCH($L$7,LenU,0))*1000,IF(OR(J21="",K21=""),"",IFERROR(IF(INDEX(PipeWT,MATCH(J21,NPSU,0),MATCH(K21,SchU,0))="","Sch n/a",INDEX(PipeOD,MATCH(J21,NPSU,0))-2*INDEX(PipeWT,MATCH(J21,NPSU,0),MATCH(K21,SchU,0))),""))) | AT21: =IF(ISNUMBER(AI21),AI21,IFERROR(INDEX(IF(CC_JobType="Decontamination",CC_TypeFillDC,CC_TypeFillCC),MATCH(E21,CC_TypeL,0)),1)) -> 1 | AU21: 1
A22: 13 | AD22: =IF(E22="Exchanger",IF(AND(ISNUMBER(S22),ISNUMBER(U22),ISNUMBER(V22)),S22*PI()/4*(U22*INDEX(LenF,MATCH($U$7,LenU,0)))^2*V22*INDEX(LenF,MATCH($V$7,LenU,0)),0)+IF(ISNUMBER(Y22),PI()/4*(Y22*INDEX(LenF,MATCH($Y$7,LenU,0)))^2*N(Z22)*INDEX(LenF,MATCH($Z$7,LenU,0))+IF(AA22="",0,IF(AA22="Conical",PI()/12*(Y22*INDEX(LenF,MATCH($Y$7,LenU,0)))^2*(0),INDEX(HeadK,MATCH(AA22,HeadU,0))*(Y22*INDEX(LenF,MATCH($Y$7,LenU,0)))^3)),0)+IF(ISNUMBER(Y22),PI()/4*(Y22*INDEX(LenF,MATCH($Y$7,LenU,0)))^2*N(AB22)*INDEX(LenF,MATCH($AB$7,LenU,0))+IF(AC22="",0,IF(AC22="Conical",PI()/12*(Y22*INDEX(LenF,MATCH($Y$7,LenU,0)))^2*(0),INDEX(HeadK,MATCH(AC22,HeadU,0))*(Y22*INDEX(LenF,MATCH($Y$7,LenU,0)))^3)),0),"") | AE22: =IF(OR(E22="",E22="Piping"),"",IF(E22="Exchanger",AQ22*AR22+IF(P22="",0,IF(P22="Conical",PI()/12*(SQRT(4*AQ22/PI()))^2*(0),INDEX(HeadK,MATCH(P22,HeadU,0))*(SQRT(4*AQ22/PI()))^3))-IF(AND(ISNUMBER(S22),ISNUMBER(V22)),S22*PI()/4*AP22^2*V22*INDEX(LenF,MATCH($V$7,LenU,0)),0),IF(ISNUMBER(N22),PI()/4*(N22*INDEX(LenF,MATCH($N$7,LenU,0)))^2*N(O22)*INDEX(LenF,MATCH($O$7,LenU,0))+IF(P22="",0,IF(P22="Conical",PI()/12*(N22*INDEX(LenF,MATCH($N$7,LenU,0)))^2*(N(R22)*INDEX(LenF,MATCH($R$7,LenU,0))),INDEX(HeadK,MATCH(P22,HeadU,0))*(N22*INDEX(LenF,MATCH($N$7,LenU,0)))^3))+IF(Q22="",0,IF(Q22="Conical",PI()/12*(N22*INDEX(LenF,MATCH($N$7,LenU,0)))^2*(N(R22)*INDEX(LenF,MATCH($R$7,LenU,0))),INDEX(HeadK,MATCH(Q22,HeadU,0))*(N22*INDEX(LenF,MATCH($N$7,LenU,0)))^3)),0))) | AF22: =IF(E22<>"Piping","",IF(AND(ISNUMBER(AS22),ISNUMBER(M22)),PI()/4*(AS22/1000)^2*M22*INDEX(LenF,MATCH($M$7,LenU,0)),0)) | AG22: =IF(E22="","",N(AD22)+N(AE22)+N(AF22)) | AH22: =IF(ISNUMBER(I22),I22*INDEX(WtF,MATCH($I$7,WtU,0))/CC_WaterRho,"") | AM22: =IF(AO22="","",AO22*IF(ISNUMBER(AK22),AK22,CC_DefFills)*(1+IF(ISNUMBER(AL22),AL22,CC_DefAllow))) | AN22: =IF(G22="Given volume",IF(ISNUMBER(H22),H22*INDEX(VolF,MATCH($H$7,VolU,0)),""),IF(G22="Water weight",AH22,IF(N(AG22)=0,"",AG22))) | AO22: =IF(N(AN22)=0,"",AN22*AT22*IF(ISNUMBER(AJ22),AJ22,CC_DefCirc)) | AP22: =IF(ISNUMBER(T22),T22*INDEX(LenF,MATCH($T$7,LenU,0)),IF(ISNUMBER(W22),W22*INDEX(LenF,MATCH($W$7,LenU,0))/CC_PitchRatio,0)) -> 0 | AQ22: =IF(ISNUMBER(N22),PI()/4*(N22*INDEX(LenF,MATCH($N$7,LenU,0)))^2,IF(AND(ISNUMBER(S22),ISNUMBER(W22),X22<>""),S22*(W22*INDEX(LenF,MATCH($W$7,LenU,0)))^2*INDEX(LayoutF,MATCH(X22,LayoutU,0)),0)) -> 0 | AR22: =IF(ISNUMBER(O22),O22*INDEX(LenF,MATCH($O$7,LenU,0)),IF(ISNUMBER(V22),V22*INDEX(LenF,MATCH($V$7,LenU,0)),0)) -> 0 | AS22: =IF(ISNUMBER(L22),L22*INDEX(LenF,MATCH($L$7,LenU,0))*1000,IF(OR(J22="",K22=""),"",IFERROR(IF(INDEX(PipeWT,MATCH(J22,NPSU,0),MATCH(K22,SchU,0))="","Sch n/a",INDEX(PipeOD,MATCH(J22,NPSU,0))-2*INDEX(PipeWT,MATCH(J22,NPSU,0),MATCH(K22,SchU,0))),""))) | AT22: =IF(ISNUMBER(AI22),AI22,IFERROR(INDEX(IF(CC_JobType="Decontamination",CC_TypeFillDC,CC_TypeFillCC),MATCH(E22,CC_TypeL,0)),1)) -> 1 | AU22: 1
A23: 14 | AD23: =IF(E23="Exchanger",IF(AND(ISNUMBER(S23),ISNUMBER(U23),ISNUMBER(V23)),S23*PI()/4*(U23*INDEX(LenF,MATCH($U$7,LenU,0)))^2*V23*INDEX(LenF,MATCH($V$7,LenU,0)),0)+IF(ISNUMBER(Y23),PI()/4*(Y23*INDEX(LenF,MATCH($Y$7,LenU,0)))^2*N(Z23)*INDEX(LenF,MATCH($Z$7,LenU,0))+IF(AA23="",0,IF(AA23="Conical",PI()/12*(Y23*INDEX(LenF,MATCH($Y$7,LenU,0)))^2*(0),INDEX(HeadK,MATCH(AA23,HeadU,0))*(Y23*INDEX(LenF,MATCH($Y$7,LenU,0)))^3)),0)+IF(ISNUMBER(Y23),PI()/4*(Y23*INDEX(LenF,MATCH($Y$7,LenU,0)))^2*N(AB23)*INDEX(LenF,MATCH($AB$7,LenU,0))+IF(AC23="",0,IF(AC23="Conical",PI()/12*(Y23*INDEX(LenF,MATCH($Y$7,LenU,0)))^2*(0),INDEX(HeadK,MATCH(AC23,HeadU,0))*(Y23*INDEX(LenF,MATCH($Y$7,LenU,0)))^3)),0),"") | AE23: =IF(OR(E23="",E23="Piping"),"",IF(E23="Exchanger",AQ23*AR23+IF(P23="",0,IF(P23="Conical",PI()/12*(SQRT(4*AQ23/PI()))^2*(0),INDEX(HeadK,MATCH(P23,HeadU,0))*(SQRT(4*AQ23/PI()))^3))-IF(AND(ISNUMBER(S23),ISNUMBER(V23)),S23*PI()/4*AP23^2*V23*INDEX(LenF,MATCH($V$7,LenU,0)),0),IF(ISNUMBER(N23),PI()/4*(N23*INDEX(LenF,MATCH($N$7,LenU,0)))^2*N(O23)*INDEX(LenF,MATCH($O$7,LenU,0))+IF(P23="",0,IF(P23="Conical",PI()/12*(N23*INDEX(LenF,MATCH($N$7,LenU,0)))^2*(N(R23)*INDEX(LenF,MATCH($R$7,LenU,0))),INDEX(HeadK,MATCH(P23,HeadU,0))*(N23*INDEX(LenF,MATCH($N$7,LenU,0)))^3))+IF(Q23="",0,IF(Q23="Conical",PI()/12*(N23*INDEX(LenF,MATCH($N$7,LenU,0)))^2*(N(R23)*INDEX(LenF,MATCH($R$7,LenU,0))),INDEX(HeadK,MATCH(Q23,HeadU,0))*(N23*INDEX(LenF,MATCH($N$7,LenU,0)))^3)),0))) | AF23: =IF(E23<>"Piping","",IF(AND(ISNUMBER(AS23),ISNUMBER(M23)),PI()/4*(AS23/1000)^2*M23*INDEX(LenF,MATCH($M$7,LenU,0)),0)) | AG23: =IF(E23="","",N(AD23)+N(AE23)+N(AF23)) | AH23: =IF(ISNUMBER(I23),I23*INDEX(WtF,MATCH($I$7,WtU,0))/CC_WaterRho,"") | AM23: =IF(AO23="","",AO23*IF(ISNUMBER(AK23),AK23,CC_DefFills)*(1+IF(ISNUMBER(AL23),AL23,CC_DefAllow))) | AN23: =IF(G23="Given volume",IF(ISNUMBER(H23),H23*INDEX(VolF,MATCH($H$7,VolU,0)),""),IF(G23="Water weight",AH23,IF(N(AG23)=0,"",AG23))) | AO23: =IF(N(AN23)=0,"",AN23*AT23*IF(ISNUMBER(AJ23),AJ23,CC_DefCirc)) | AP23: =IF(ISNUMBER(T23),T23*INDEX(LenF,MATCH($T$7,LenU,0)),IF(ISNUMBER(W23),W23*INDEX(LenF,MATCH($W$7,LenU,0))/CC_PitchRatio,0)) -> 0 | AQ23: =IF(ISNUMBER(N23),PI()/4*(N23*INDEX(LenF,MATCH($N$7,LenU,0)))^2,IF(AND(ISNUMBER(S23),ISNUMBER(W23),X23<>""),S23*(W23*INDEX(LenF,MATCH($W$7,LenU,0)))^2*INDEX(LayoutF,MATCH(X23,LayoutU,0)),0)) -> 0 | AR23: =IF(ISNUMBER(O23),O23*INDEX(LenF,MATCH($O$7,LenU,0)),IF(ISNUMBER(V23),V23*INDEX(LenF,MATCH($V$7,LenU,0)),0)) -> 0 | AS23: =IF(ISNUMBER(L23),L23*INDEX(LenF,MATCH($L$7,LenU,0))*1000,IF(OR(J23="",K23=""),"",IFERROR(IF(INDEX(PipeWT,MATCH(J23,NPSU,0),MATCH(K23,SchU,0))="","Sch n/a",INDEX(PipeOD,MATCH(J23,NPSU,0))-2*INDEX(PipeWT,MATCH(J23,NPSU,0),MATCH(K23,SchU,0))),""))) | AT23: =IF(ISNUMBER(AI23),AI23,IFERROR(INDEX(IF(CC_JobType="Decontamination",CC_TypeFillDC,CC_TypeFillCC),MATCH(E23,CC_TypeL,0)),1)) -> 1 | AU23: 1
A24: 15 | AD24: =IF(E24="Exchanger",IF(AND(ISNUMBER(S24),ISNUMBER(U24),ISNUMBER(V24)),S24*PI()/4*(U24*INDEX(LenF,MATCH($U$7,LenU,0)))^2*V24*INDEX(LenF,MATCH($V$7,LenU,0)),0)+IF(ISNUMBER(Y24),PI()/4*(Y24*INDEX(LenF,MATCH($Y$7,LenU,0)))^2*N(Z24)*INDEX(LenF,MATCH($Z$7,LenU,0))+IF(AA24="",0,IF(AA24="Conical",PI()/12*(Y24*INDEX(LenF,MATCH($Y$7,LenU,0)))^2*(0),INDEX(HeadK,MATCH(AA24,HeadU,0))*(Y24*INDEX(LenF,MATCH($Y$7,LenU,0)))^3)),0)+IF(ISNUMBER(Y24),PI()/4*(Y24*INDEX(LenF,MATCH($Y$7,LenU,0)))^2*N(AB24)*INDEX(LenF,MATCH($AB$7,LenU,0))+IF(AC24="",0,IF(AC24="Conical",PI()/12*(Y24*INDEX(LenF,MATCH($Y$7,LenU,0)))^2*(0),INDEX(HeadK,MATCH(AC24,HeadU,0))*(Y24*INDEX(LenF,MATCH($Y$7,LenU,0)))^3)),0),"") | AE24: =IF(OR(E24="",E24="Piping"),"",IF(E24="Exchanger",AQ24*AR24+IF(P24="",0,IF(P24="Conical",PI()/12*(SQRT(4*AQ24/PI()))^2*(0),INDEX(HeadK,MATCH(P24,HeadU,0))*(SQRT(4*AQ24/PI()))^3))-IF(AND(ISNUMBER(S24),ISNUMBER(V24)),S24*PI()/4*AP24^2*V24*INDEX(LenF,MATCH($V$7,LenU,0)),0),IF(ISNUMBER(N24),PI()/4*(N24*INDEX(LenF,MATCH($N$7,LenU,0)))^2*N(O24)*INDEX(LenF,MATCH($O$7,LenU,0))+IF(P24="",0,IF(P24="Conical",PI()/12*(N24*INDEX(LenF,MATCH($N$7,LenU,0)))^2*(N(R24)*INDEX(LenF,MATCH($R$7,LenU,0))),INDEX(HeadK,MATCH(P24,HeadU,0))*(N24*INDEX(LenF,MATCH($N$7,LenU,0)))^3))+IF(Q24="",0,IF(Q24="Conical",PI()/12*(N24*INDEX(LenF,MATCH($N$7,LenU,0)))^2*(N(R24)*INDEX(LenF,MATCH($R$7,LenU,0))),INDEX(HeadK,MATCH(Q24,HeadU,0))*(N24*INDEX(LenF,MATCH($N$7,LenU,0)))^3)),0))) | AF24: =IF(E24<>"Piping","",IF(AND(ISNUMBER(AS24),ISNUMBER(M24)),PI()/4*(AS24/1000)^2*M24*INDEX(LenF,MATCH($M$7,LenU,0)),0)) | AG24: =IF(E24="","",N(AD24)+N(AE24)+N(AF24)) | AH24: =IF(ISNUMBER(I24),I24*INDEX(WtF,MATCH($I$7,WtU,0))/CC_WaterRho,"") | AM24: =IF(AO24="","",AO24*IF(ISNUMBER(AK24),AK24,CC_DefFills)*(1+IF(ISNUMBER(AL24),AL24,CC_DefAllow))) | AN24: =IF(G24="Given volume",IF(ISNUMBER(H24),H24*INDEX(VolF,MATCH($H$7,VolU,0)),""),IF(G24="Water weight",AH24,IF(N(AG24)=0,"",AG24))) | AO24: =IF(N(AN24)=0,"",AN24*AT24*IF(ISNUMBER(AJ24),AJ24,CC_DefCirc)) | AP24: =IF(ISNUMBER(T24),T24*INDEX(LenF,MATCH($T$7,LenU,0)),IF(ISNUMBER(W24),W24*INDEX(LenF,MATCH($W$7,LenU,0))/CC_PitchRatio,0)) -> 0 | AQ24: =IF(ISNUMBER(N24),PI()/4*(N24*INDEX(LenF,MATCH($N$7,LenU,0)))^2,IF(AND(ISNUMBER(S24),ISNUMBER(W24),X24<>""),S24*(W24*INDEX(LenF,MATCH($W$7,LenU,0)))^2*INDEX(LayoutF,MATCH(X24,LayoutU,0)),0)) -> 0 | AR24: =IF(ISNUMBER(O24),O24*INDEX(LenF,MATCH($O$7,LenU,0)),IF(ISNUMBER(V24),V24*INDEX(LenF,MATCH($V$7,LenU,0)),0)) -> 0 | AS24: =IF(ISNUMBER(L24),L24*INDEX(LenF,MATCH($L$7,LenU,0))*1000,IF(OR(J24="",K24=""),"",IFERROR(IF(INDEX(PipeWT,MATCH(J24,NPSU,0),MATCH(K24,SchU,0))="","Sch n/a",INDEX(PipeOD,MATCH(J24,NPSU,0))-2*INDEX(PipeWT,MATCH(J24,NPSU,0),MATCH(K24,SchU,0))),""))) | AT24: =IF(ISNUMBER(AI24),AI24,IFERROR(INDEX(IF(CC_JobType="Decontamination",CC_TypeFillDC,CC_TypeFillCC),MATCH(E24,CC_TypeL,0)),1)) -> 1 | AU24: 1
A25: 16 | AD25: =IF(E25="Exchanger",IF(AND(ISNUMBER(S25),ISNUMBER(U25),ISNUMBER(V25)),S25*PI()/4*(U25*INDEX(LenF,MATCH($U$7,LenU,0)))^2*V25*INDEX(LenF,MATCH($V$7,LenU,0)),0)+IF(ISNUMBER(Y25),PI()/4*(Y25*INDEX(LenF,MATCH($Y$7,LenU,0)))^2*N(Z25)*INDEX(LenF,MATCH($Z$7,LenU,0))+IF(AA25="",0,IF(AA25="Conical",PI()/12*(Y25*INDEX(LenF,MATCH($Y$7,LenU,0)))^2*(0),INDEX(HeadK,MATCH(AA25,HeadU,0))*(Y25*INDEX(LenF,MATCH($Y$7,LenU,0)))^3)),0)+IF(ISNUMBER(Y25),PI()/4*(Y25*INDEX(LenF,MATCH($Y$7,LenU,0)))^2*N(AB25)*INDEX(LenF,MATCH($AB$7,LenU,0))+IF(AC25="",0,IF(AC25="Conical",PI()/12*(Y25*INDEX(LenF,MATCH($Y$7,LenU,0)))^2*(0),INDEX(HeadK,MATCH(AC25,HeadU,0))*(Y25*INDEX(LenF,MATCH($Y$7,LenU,0)))^3)),0),"") | AE25: =IF(OR(E25="",E25="Piping"),"",IF(E25="Exchanger",AQ25*AR25+IF(P25="",0,IF(P25="Conical",PI()/12*(SQRT(4*AQ25/PI()))^2*(0),INDEX(HeadK,MATCH(P25,HeadU,0))*(SQRT(4*AQ25/PI()))^3))-IF(AND(ISNUMBER(S25),ISNUMBER(V25)),S25*PI()/4*AP25^2*V25*INDEX(LenF,MATCH($V$7,LenU,0)),0),IF(ISNUMBER(N25),PI()/4*(N25*INDEX(LenF,MATCH($N$7,LenU,0)))^2*N(O25)*INDEX(LenF,MATCH($O$7,LenU,0))+IF(P25="",0,IF(P25="Conical",PI()/12*(N25*INDEX(LenF,MATCH($N$7,LenU,0)))^2*(N(R25)*INDEX(LenF,MATCH($R$7,LenU,0))),INDEX(HeadK,MATCH(P25,HeadU,0))*(N25*INDEX(LenF,MATCH($N$7,LenU,0)))^3))+IF(Q25="",0,IF(Q25="Conical",PI()/12*(N25*INDEX(LenF,MATCH($N$7,LenU,0)))^2*(N(R25)*INDEX(LenF,MATCH($R$7,LenU,0))),INDEX(HeadK,MATCH(Q25,HeadU,0))*(N25*INDEX(LenF,MATCH($N$7,LenU,0)))^3)),0))) | AF25: =IF(E25<>"Piping","",IF(AND(ISNUMBER(AS25),ISNUMBER(M25)),PI()/4*(AS25/1000)^2*M25*INDEX(LenF,MATCH($M$7,LenU,0)),0)) | AG25: =IF(E25="","",N(AD25)+N(AE25)+N(AF25)) | AH25: =IF(ISNUMBER(I25),I25*INDEX(WtF,MATCH($I$7,WtU,0))/CC_WaterRho,"") | AM25: =IF(AO25="","",AO25*IF(ISNUMBER(AK25),AK25,CC_DefFills)*(1+IF(ISNUMBER(AL25),AL25,CC_DefAllow))) | AN25: =IF(G25="Given volume",IF(ISNUMBER(H25),H25*INDEX(VolF,MATCH($H$7,VolU,0)),""),IF(G25="Water weight",AH25,IF(N(AG25)=0,"",AG25))) | AO25: =IF(N(AN25)=0,"",AN25*AT25*IF(ISNUMBER(AJ25),AJ25,CC_DefCirc)) | AP25: =IF(ISNUMBER(T25),T25*INDEX(LenF,MATCH($T$7,LenU,0)),IF(ISNUMBER(W25),W25*INDEX(LenF,MATCH($W$7,LenU,0))/CC_PitchRatio,0)) -> 0 | AQ25: =IF(ISNUMBER(N25),PI()/4*(N25*INDEX(LenF,MATCH($N$7,LenU,0)))^2,IF(AND(ISNUMBER(S25),ISNUMBER(W25),X25<>""),S25*(W25*INDEX(LenF,MATCH($W$7,LenU,0)))^2*INDEX(LayoutF,MATCH(X25,LayoutU,0)),0)) -> 0 | AR25: =IF(ISNUMBER(O25),O25*INDEX(LenF,MATCH($O$7,LenU,0)),IF(ISNUMBER(V25),V25*INDEX(LenF,MATCH($V$7,LenU,0)),0)) -> 0 | AS25: =IF(ISNUMBER(L25),L25*INDEX(LenF,MATCH($L$7,LenU,0))*1000,IF(OR(J25="",K25=""),"",IFERROR(IF(INDEX(PipeWT,MATCH(J25,NPSU,0),MATCH(K25,SchU,0))="","Sch n/a",INDEX(PipeOD,MATCH(J25,NPSU,0))-2*INDEX(PipeWT,MATCH(J25,NPSU,0),MATCH(K25,SchU,0))),""))) | AT25: =IF(ISNUMBER(AI25),AI25,IFERROR(INDEX(IF(CC_JobType="Decontamination",CC_TypeFillDC,CC_TypeFillCC),MATCH(E25,CC_TypeL,0)),1)) -> 1 | AU25: 1
